Workbook

Sheet DO NOT EDIT - Client List
A1: Household Name | B1: City | C1: Community | D1: Region | E1: Last Review | F1: New Review Date | G1: Special Notes | H1: Copy/Material Count | I1: Advisor Number/Kathleen? | J1: Done?
A2: WEST STOCKBRIDGE, TOWN OF | B2: WEST STOCKBRIDGE | C2: West Stockbridge | D2: =_xlfn.XLOOKUP(C2,'Territory List'!$D$2:$D$352,'Territory List'!$G$2:$G$352) -> 1 | E2: =VLOOKUP(A2,'1-Sue'!$A$2:$H$16,5,FALSE) -> 4/28 @1pm (meet in Cheshire) | F2: =VLOOKUP(A2,'1-Sue'!A15:J36,9,FALSE) -> 9/14 @ 12:30 | G2: =_xlfn.IFNA(VLOOKUP(A2,'1-Sue'!$A$2:$H$16,6,FALSE)," ") -> - | H2: =_xlfn.IFNA(VLOOKUP(A2,'1-Sue'!$A$2:$H$16,7,FALSE)," ") -> - | I2: =_xlfn.IFNA(VLOOKUP(A2,'1-Sue'!$A$2:$H$16,8,FALSE)," ") -> - | J2: =VLOOKUP(A2,'1-Sue'!$A$1:$J$24,10,FALSE) -> 0
A3: STOCKBRIDGE, TOWN OF | B3: STOCKBRIDGE | C3: Stockbridge | D3: =_xlfn.XLOOKUP(C3,'Territory List'!$D$2:$D$352,'Territory List'!$G$2:$G$352) -> 1 | E3: =VLOOKUP(A3,'1-Sue'!$A$2:$H$16,5,FALSE) -> 5/4 @ 12pm LUNCH | F3: =VLOOKUP(A3,'1-Sue'!A14:J35,9,FALSE) -> 0 | G3: =_xlfn.IFNA(VLOOKUP(A3,'1-Sue'!$A$2:$H$16,6,FALSE)," ") -> - | H3: =_xlfn.IFNA(VLOOKUP(A3,'1-Sue'!$A$2:$H$16,7,FALSE)," ") -> 0 | I3: =_xlfn.IFNA(VLOOKUP(A3,'1-Sue'!$A$2:$H$16,8,FALSE)," ") -> - | J3: =VLOOKUP(A3,'1-Sue'!$A$1:$J$24,10,FALSE) -> 0
A4: RICHMOND, TOWN OF | B4: Richmond | C4: Richmond | D4: =_xlfn.XLOOKUP(C4,'Territory List'!$D$2:$D$352,'Territory List'!$G$2:$G$352) -> 1 | E4: =VLOOKUP(A4,'1-Sue'!$A$2:$H$16,5,FALSE) -> 5/13 @ 3:30 | F4: =VLOOKUP(A4,'1-Sue'!A13:J34,9,FALSE) -> 9/17 @ 11:30 (lunch) | G4: =_xlfn.IFNA(VLOOKUP(A4,'1-Sue'!$A$2:$H$16,6,FALSE)," ") -> Lunch | H4: =_xlfn.IFNA(VLOOKUP(A4,'1-Sue'!$A$2:$H$16,7,FALSE)," ") -> - | I4: =_xlfn.IFNA(VLOOKUP(A4,'1-Sue'!$A$2:$H$16,8,FALSE)," ") -> - | J4: =VLOOKUP(A4,'1-Sue'!$A$1:$J$24,10,FALSE) -> 0
A5: OTIS, TOWN OF | B5: OTIS | C5: Otis | D5: =_xlfn.XLOOKUP(C5,'Territory List'!$D$2:$D$352,'Territory List'!$G$2:$G$352) -> 1 | E5: =VLOOKUP(A5,'1-Sue'!$A$2:$H$16,5,FALSE) -> 0 | F5: =VLOOKUP(A5,'1-Sue'!A12:J33,9,FALSE) -> 9/30 @10:30 | G5: =_xlfn.IFNA(VLOOKUP(A5,'1-Sue'!$A$2:$H$16,6,FALSE)," ") -> - | H5: =_xlfn.IFNA(VLOOKUP(A5,'1-Sue'!$A$2:$H$16,7,FALSE)," ") -> 0 | I5: =_xlfn.IFNA(VLOOKUP(A5,'1-Sue'!$A$2:$H$16,8,FALSE)," ") -> - | J5: =VLOOKUP(A5,'1-Sue'!$A$1:$J$24,10,FALSE) -> 0
A6: LENOX, TOWN OF | B6: LENOX | C6: Lenox | D6: =_xlfn.XLOOKUP(C6,'Territory List'!$D$2:$D$352,'Territory List'!$G$2:$G$352) -> 1 | E6: =VLOOKUP(A6,'1-Sue'!$A$2:$H$16,5,FALSE) -> Sent reviews | F6: =VLOOKUP(A6,'1-Sue'!A10:J31,9,FALSE) -> 9/17 @ 9:30 | G6: =_xlfn.IFNA(VLOOKUP(A6,'1-Sue'!$A$2:$H$16,6,FALSE)," ") -> Lunch | H6: =_xlfn.IFNA(VLOOKUP(A6,'1-Sue'!$A$2:$H$16,7,FALSE)," ") -> 0 | I6: =_xlfn.IFNA(VLOOKUP(A6,'1-Sue'!$A$2:$H$16,8,FALSE)," ") -> - | J6: =VLOOKUP(A6,'1-Sue'!$A$1:$J$24,10,FALSE) -> 0
A7: LEE, TOWN OF | B7: LEE | C7: Lee | D7: =_xlfn.XLOOKUP(C7,'Territory List'!$D$2:$D$352,'Territory List'!$G$2:$G$352) -> 1 | E7: =VLOOKUP(A7,'1-Sue'!$A$2:$H$16,5,FALSE) -> sent email | F7: =VLOOKUP(A7,'1-Sue'!A8:J30,9,FALSE) -> 0 | G7: =_xlfn.IFNA(VLOOKUP(A7,'1-Sue'!$A$2:$H$16,6,FALSE)," ") -> - | H7: =_xlfn.IFNA(VLOOKUP(A7,'1-Sue'!$A$2:$H$16,7,FALSE)," ") -> Sue can't do this one (conflict of interest) | I7: =_xlfn.IFNA(VLOOKUP(A7,'1-Sue'!$A$2:$H$16,8,FALSE)," ") -> - | J7: =VLOOKUP(A7,'1-Sue'!$A$1:$J$24,10,FALSE) -> 0
A8: LAKE BUEL PRESERVATION DISTRICT | B8: NEW MARLBOROUGH | C8: New Marlborough | D8: =_xlfn.XLOOKUP(C8,'Territory List'!$D$2:$D$352,'Territory List'!$G$2:$G$352) -> 1 | E8: =VLOOKUP(A8,'1-Sue'!$A$2:$H$16,5,FALSE) -> 5/13 @ 10:30 | F8: =VLOOKUP(A8,'1-Sue'!A11:J32,9,FALSE) -> 0 | G8: =_xlfn.IFNA(VLOOKUP(A8,'1-Sue'!$A$2:$H$16,6,FALSE)," ") -> - | H8: =_xlfn.IFNA(VLOOKUP(A8,'1-Sue'!$A$2:$H$16,7,FALSE)," ") -> - | I8: =_xlfn.IFNA(VLOOKUP(A8,'1-Sue'!$A$2:$H$16,8,FALSE)," ") -> - | J8: =VLOOKUP(A8,'1-Sue'!$A$1:$J$24,10,FALSE) -> 0
A9: GREAT BARRINGTON, TOWN OF | B9: GREAT BARRINGTON | C9: Great Barrington | D9: =_xlfn.XLOOKUP(C9,'Territory List'!$D$2:$D$352,'Territory List'!$G$2:$G$352) -> 1 | E9: =VLOOKUP(A9,'1-Sue'!$A$2:$H$16,5,FALSE) -> 5/13/ @ noon ? | F9: =VLOOKUP(A9,'1-Sue'!A7:J29,9,FALSE) -> 0 | G9: =_xlfn.IFNA(VLOOKUP(A9,'1-Sue'!$A$2:$H$16,6,FALSE)," ") -> - | H9: =_xlfn.IFNA(VLOOKUP(A9,'1-Sue'!$A$2:$H$16,7,FALSE)," ") -> - | I9: =_xlfn.IFNA(VLOOKUP(A9,'1-Sue'!$A$2:$H$16,8,FALSE)," ") -> - | J9: =VLOOKUP(A9,'1-Sue'!$A$1:$J$24,10,FALSE) -> 0
A10: MONTEREY, TOWN OF | B10: MONTEREY | C10: Monterey | D10: =_xlfn.XLOOKUP(C10,'Territory List'!$D$2:$D$352,'Territory List'!$G$2:$G$352) -> 1 | E10: =VLOOKUP(A10,'1-Sue'!$A$2:$H$16,5,FALSE) -> 0 | F10: =VLOOKUP(A10,'1-Sue'!A8:J30,9,FALSE) -> 0 | G10: =_xlfn.IFNA(VLOOKUP(A10,'1-Sue'!$A$2:$H$16,6,FALSE)," ") -> - | H10: =_xlfn.IFNA(VLOOKUP(A10,'1-Sue'!$A$2:$H$16,7,FALSE)," ") -> - | I10: =_xlfn.IFNA(VLOOKUP(A10,'1-Sue'!$A$2:$H$16,8,FALSE)," ") -> - | J10: =VLOOKUP(A10,'1-Sue'!$A$1:$J$24,10,FALSE) -> 0
A11: EGREMONT, TOWN OF | B11: EGREMONT | C11: Egremont | D11: =_xlfn.XLOOKUP(C11,'Territory List'!$D$2:$D$352,'Territory List'!$G$2:$G$352) -> 1 | E11: =VLOOKUP(A11,'1-Sue'!$A$2:$H$16,5,FALSE) -> 45739 | F11: =VLOOKUP(A11,'1-Sue'!A6:J28,9,FALSE) -> 0 | G11: =_xlfn.IFNA(VLOOKUP(A11,'1-Sue'!$A$2:$H$16,6,FALSE)," ") -> - | H11: =_xlfn.IFNA(VLOOKUP(A11,'1-Sue'!$A$2:$H$16,7,FALSE)," ") -> - | I11: =_xlfn.IFNA(VLOOKUP(A11,'1-Sue'!$A$2:$H$16,8,FALSE)," ") -> - | J11: =VLOOKUP(A11,'1-Sue'!$A$1:$J$24,10,FALSE) -> 0
A12: CHESTER, TOWN OF | B12: CHESTER | C12: Chester | D12: =_xlfn.XLOOKUP(C12,'Territory List'!$D$2:$D$352,'Territory List'!$G$2:$G$352) -> 1 | E12: =VLOOKUP(A12,'1-Sue'!$A$2:$H$16,5,FALSE) -> 46001 | F12: =VLOOKUP(A12,'1-Sue'!A4:J27,9,FALSE) -> 0 | G12: =_xlfn.IFNA(VLOOKUP(A12,'1-Sue'!$A$2:$H$16,6,FALSE)," ") -> - | H12: =_xlfn.IFNA(VLOOKUP(A12,'1-Sue'!$A$2:$H$16,7,FALSE)," ") -> Sara H (Blandford, Chester, Monterey) | I12: =_xlfn.IFNA(VLOOKUP(A12,'1-Sue'!$A$2:$H$16,8,FALSE)," ") -> - | J12: =VLOOKUP(A12,'1-Sue'!$A$1:$J$24,10,FALSE) -> 0
A13: BLANDFORD, TOWN OF | B13: BLANDFORD | C13: Blandford | D13: =_xlfn.XLOOKUP(C13,'Territory List'!$D$2:$D$352,'Territory List'!$G$2:$G$352) -> 1 | E13: =VLOOKUP(A13,'1-Sue'!$A$2:$H$16,5,FALSE) -> 46001 | F13: =VLOOKUP(A13,'1-Sue'!A3:J26,9,FALSE) -> 0 | G13: =_xlfn.IFNA(VLOOKUP(A13,'1-Sue'!$A$2:$H$16,6,FALSE)," ") -> - | H13: =_xlfn.IFNA(VLOOKUP(A13,'1-Sue'!$A$2:$H$16,7,FALSE)," ") -> Sara H (Blandford, Chester, Monterey) | I13: =_xlfn.IFNA(VLOOKUP(A13,'1-Sue'!$A$2:$H$16,8,FALSE)," ") -> - | J13: =VLOOKUP(A13,'1-Sue'!$A$1:$J$24,10,FALSE) -> 0
A14: BECKET, TOWN OF | B14: BECKET | C14: Becket | D14: =_xlfn.XLOOKUP(C14,'Territory List'!$D$2:$D$352,'Territory List'!$G$2:$G$352) -> 1 | E14: =VLOOKUP(A14,'1-Sue'!$A$2:$H$16,5,FALSE) -> 46037 | F14: =VLOOKUP(A14,'1-Sue'!$A$1:$J$24,9,FALSE) -> 8/25 @ 9 | G14: =_xlfn.IFNA(VLOOKUP(A14,'1-Sue'!$A$2:$H$16,6,FALSE)," ") -> - | H14: =_xlfn.IFNA(VLOOKUP(A14,'1-Sue'!$A$2:$H$16,7,FALSE)," ") -> - | I14: =_xlfn.IFNA(VLOOKUP(A14,'1-Sue'!$A$2:$H$16,8,FALSE)," ") -> - | J14: =VLOOKUP(A14,'1-Sue'!$A$1:$J$24,10,FALSE) -> 1
A15: BECKET BROADBAND DISTRICT | C15: Becket | D15: =_xlfn.XLOOKUP(C15,'Territory List'!$D$2:$D$352,'Territory List'!$G$2:$G$352) -> 1 | E15: =VLOOKUP(A15,'1-Sue'!$A$2:$H$16,5,FALSE) -> 46037 | F15: =VLOOKUP(A15,'1-Sue'!A2:J25,9,FALSE) -> 8/25 @9:30 | G15: =_xlfn.IFNA(VLOOKUP(A15,'1-Sue'!$A$2:$H$16,6,FALSE)," ") -> - | H15: =_xlfn.IFNA(VLOOKUP(A15,'1-Sue'!$A$2:$H$16,7,FALSE)," ") -> - | I15: =_xlfn.IFNA(VLOOKUP(A15,'1-Sue'!$A$2:$H$16,8,FALSE)," ") -> - | J15: =VLOOKUP(A15,'1-Sue'!$A$1:$J$24,10,FALSE) -> 1
A16: WINDSOR, TOWN OF | B16: WINDSOR | C16: Windsor | D16: =_xlfn.XLOOKUP(C16,'Territory List'!$D$2:$D$352,'Territory List'!$G$2:$G$352) -> 2 | E16: =VLOOKUP(A16,'2-Sue'!$A$2:$H$12,5,FALSE) -> 5/12 @ 1:30 | F16: =VLOOKUP(A16,'2-Sue'!$A$1:$J$24,9,FALSE) -> 8/25 @ 12pm | G16: =_xlfn.IFNA(VLOOKUP(A16,'2-Sue'!$A$2:$H$12,6,FALSE)," ") -> - | H16: =_xlfn.IFNA(VLOOKUP(A16,'2-Sue'!$A$2:$H$12,7,FALSE)," ") -> 3 | I16: =_xlfn.IFNA(VLOOKUP(A16,'2-Sue'!$A$2:$H$12,8,FALSE)," ") -> - | J16: =VLOOKUP(A16,'2-Sue'!$A$1:$J$24,10,FALSE) -> 1
A17: WILLIAMSTOWN, TOWN OF | B17: WILLIAMSTOWN | C17: Williamstown | D17: =_xlfn.XLOOKUP(C17,'Territory List'!$D$2:$D$352,'Territory List'!$G$2:$G$352) -> 2 | E17: =VLOOKUP(A17,'2-Sue'!$A$2:$H$12,5,FALSE) -> 3/18/2026 @ 2:00 | F17: =VLOOKUP(A17,'2-Sue'!$A$1:$J$24,9,FALSE) -> 9/16 @10am | G17: =_xlfn.IFNA(VLOOKUP(A17,'2-Sue'!$A$2:$H$12,6,FALSE)," ") -> lunch | H17: =_xlfn.IFNA(VLOOKUP(A17,'2-Sue'!$A$2:$H$12,7,FALSE)," ") -> - | I17: =_xlfn.IFNA(VLOOKUP(A17,'2-Sue'!$A$2:$H$12,8,FALSE)," ") -> - | J17: =VLOOKUP(A17,'2-Sue'!$A$1:$J$24,10,FALSE) -> 0
A18: ROWE, TOWN OF | B18: ROWE | C18: Rowe | D18: =_xlfn.XLOOKUP(C18,'Territory List'!$D$2:$D$352,'Territory List'!$G$2:$G$352) -> 2 | E18: =VLOOKUP(A18,'2-Sue'!$A$2:$H$12,5,FALSE) -> 46099 | F18: =VLOOKUP(A18,'2-Sue'!$A$1:$J$24,9,FALSE) -> 0 | G18: =_xlfn.IFNA(VLOOKUP(A18,'2-Sue'!$A$2:$H$12,6,FALSE)," ") -> - | H18: =_xlfn.IFNA(VLOOKUP(A18,'2-Sue'!$A$2:$H$12,7,FALSE)," ") -> - | I18: =_xlfn.IFNA(VLOOKUP(A18,'2-Sue'!$A$2:$H$12,8,FALSE)," ") -> - | J18: =VLOOKUP(A18,'2-Sue'!$A$1:$J$24,10,FALSE) -> 0
A19: PITTSFIELD, CITY OF | B19: PITTSFIELD | C19: Pittsfield | D19: =_xlfn.XLOOKUP(C19,'Territory List'!$D$2:$D$352,'Territory List'!$G$2:$G$352) -> 2 | E19: =VLOOKUP(A19,'2-Sue'!$A$2:$H$12,5,FALSE) -> 46108 | F19: =VLOOKUP(A19,'2-Sue'!$A$1:$J$24,9,FALSE) -> 8/27/2026 @12pm - lunch | G19: =_xlfn.IFNA(VLOOKUP(A19,'2-Sue'!$A$2:$H$12,6,FALSE)," ") -> Always offer to do lunch | H19: =_xlfn.IFNA(VLOOKUP(A19,'2-Sue'!$A$2:$H$12,7,FALSE)," ") -> 2 | I19: =_xlfn.IFNA(VLOOKUP(A19,'2-Sue'!$A$2:$H$12,8,FALSE)," ") -> - | J19: =VLOOKUP(A19,'2-Sue'!$A$1:$J$24,10,FALSE) -> 1
A20: NORTH ADAMS, CITY OF | B20: NORTH ADAMS | C20: North Adams | D20: =_xlfn.XLOOKUP(C20,'Territory List'!$D$2:$D$352,'Territory List'!$G$2:$G$352) -> 2 | E20: =VLOOKUP(A20,'2-Sue'!$A$2:$H$12,5,FALSE) -> 46099 | F20: =VLOOKUP(A20,'2-Sue'!$A$1:$J$24,9,FALSE) -> 9/9 @12pm | G20: =_xlfn.IFNA(VLOOKUP(A20,'2-Sue'!$A$2:$H$12,6,FALSE)," ") -> - | H20: =_xlfn.IFNA(VLOOKUP(A20,'2-Sue'!$A$2:$H$12,7,FALSE)," ") -> 3 | I20: =_xlfn.IFNA(VLOOKUP(A20,'2-Sue'!$A$2:$H$12,8,FALSE)," ") -> - | J20: =VLOOKUP(A20,'2-Sue'!$A$1:$J$24,10,FALSE) -> 0
A21: LANESBOROUGH, TOWN OF | B21: LANESBOROUGH | C21: Lanesborough | D21: =_xlfn.XLOOKUP(C21,'Territory List'!$D$2:$D$352,'Territory List'!$G$2:$G$352) -> 2 | E21: =VLOOKUP(A21,'2-Sue'!$A$2:$H$12,5,FALSE) -> 5/12 @ 10:30 | F21: =VLOOKUP(A21,'2-Sue'!$A$1:$J$24,9,FALSE) -> 9/17 @ 11:30 (lunch) | G21: =_xlfn.IFNA(VLOOKUP(A21,'2-Sue'!$A$2:$H$12,6,FALSE)," ") -> Do with Lanesborough Water District | H21: =_xlfn.IFNA(VLOOKUP(A21,'2-Sue'!$A$2:$H$12,7,FALSE)," ") -> - | I21: =_xlfn.IFNA(VLOOKUP(A21,'2-Sue'!$A$2:$H$12,8,FALSE)," ") -> - | J21: =VLOOKUP(A21,'2-Sue'!$A$1:$J$24,10,FALSE) -> 0
A22: LANESBOROUGH VILLAGE FIRE & WATER DISTRICT | B22: Lanesborough | C22: Lanesborough | D22: =_xlfn.XLOOKUP(C22,'Territory List'!$D$2:$D$352,'Territory List'!$G$2:$G$352) -> 2 | E22: =VLOOKUP(A22,'2-Sue'!$A$2:$H$12,5,FALSE) -> 5/12 @12pm | F22: =VLOOKUP(A22,'2-Sue'!$A$1:$J$24,9,FALSE) -> 8/28 @ 12:30 | G22: =_xlfn.IFNA(VLOOKUP(A22,'2-Sue'!$A$2:$H$12,6,FALSE)," ") -> Treasurer works in Lanesborough/do same day | H22: =_xlfn.IFNA(VLOOKUP(A22,'2-Sue'!$A$2:$H$12,7,FALSE)," ") -> - | I22: =_xlfn.IFNA(VLOOKUP(A22,'2-Sue'!$A$2:$H$12,8,FALSE)," ") -> - | J22: =VLOOKUP(A22,'2-Sue'!$A$1:$J$24,10,FALSE) -> 0
A23: CUMMINGTON, TOWN OF | B23: CUMMINGTON | C23: Cummington | D23: =_xlfn.XLOOKUP(C23,'Territory List'!$D$2:$D$352,'Territory List'!$G$2:$G$352) -> 2 | E23: =VLOOKUP(A23,'2-Sue'!$A$2:$H$12,5,FALSE) -> 46030 | F23: =VLOOKUP(A23,'2-Sue'!$A$1:$J$24,9,FALSE) -> 9/10 @9:30 | G23: =_xlfn.IFNA(VLOOKUP(A23,'2-Sue'!$A$2:$H$12,6,FALSE)," ") -> Allan K also in Goshen | H23: =_xlfn.IFNA(VLOOKUP(A23,'2-Sue'!$A$2:$H$12,7,FALSE)," ") -> - | I23: =_xlfn.IFNA(VLOOKUP(A23,'2-Sue'!$A$2:$H$12,8,FALSE)," ") -> - | J23: =VLOOKUP(A23,'2-Sue'!$A$1:$J$24,10,FALSE) -> 0
A24: CHESHIRE, TOWN OF | B24: CHESHIRE | C24: Cheshire | D24: =_xlfn.XLOOKUP(C24,'Territory List'!$D$2:$D$352,'Territory List'!$G$2:$G$352) -> 2 | E24: =VLOOKUP(A24,'2-Sue'!$A$2:$H$12,5,FALSE) -> 46140 | F24: =VLOOKUP(A24,'2-Sue'!$A$1:$J$24,9,FALSE) -> 9/14 @12:30 in W. SB | G24: =_xlfn.IFNA(VLOOKUP(A24,'2-Sue'!$A$2:$H$12,6,FALSE)," ") -> - | H24: =_xlfn.IFNA(VLOOKUP(A24,'2-Sue'!$A$2:$H$12,7,FALSE)," ") -> 3 | I24: =_xlfn.IFNA(VLOOKUP(A24,'2-Sue'!$A$2:$H$12,8,FALSE)," ") -> - | J24: =VLOOKUP(A24,'2-Sue'!$A$1:$J$24,10,FALSE) -> 0
A25: ADAMS, TOWN OF | B25: ADAMS | C25: Adams | D25: =_xlfn.XLOOKUP(C25,'Territory List'!$D$2:$D$352,'Territory List'!$G$2:$G$352) -> 2 | E25: =VLOOKUP(A25,'2-Sue'!$A$2:$H$12,5,FALSE) -> 46050 | F25: =VLOOKUP(A25,'2-Sue'!$A$1:$J$24,9,FALSE) -> 9/9 @9am | G25: =_xlfn.IFNA(VLOOKUP(A25,'2-Sue'!$A$2:$H$12,6,FALSE)," ") -> - | H25: =_xlfn.IFNA(VLOOKUP(A25,'2-Sue'!$A$2:$H$12,7,FALSE)," ") -> 3 | I25: =_xlfn.IFNA(VLOOKUP(A25,'2-Sue'!$A$2:$H$12,8,FALSE)," ") -> - | J25: =VLOOKUP(A25,'2-Sue'!$A$1:$J$24,10,FALSE) -> 0
A26: GOSHEN, TOWN OF | B26: GOSHEN | C26: Goshen | D26: =_xlfn.XLOOKUP(C26,'Territory List'!$D$2:$D$352,'Territory List'!$G$2:$G$352) -> 2 | E26: =VLOOKUP(A26,'2-Sue'!$A$2:$F$21,3,FALSE) -> 46030 | F26: =VLOOKUP(A26,'2-Sue'!$A$1:$H$40,7,FALSE) -> - | G26: =VLOOKUP(A26,'2-Sue'!$A$2:$F$21,6,FALSE) -> - | H26: =VLOOKUP(A26,'2-Sue'!$A$2:$J$21,7,FALSE) -> - | I26: =VLOOKUP(A26,'2-Sue'!$A$2:$F$21,6,FALSE) -> - | J26: =VLOOKUP(A26,'2-Sue'!$A$1:$H$40,8,FALSE) -> -
A27: WHATELY, TOWN OF | B27: WHATELY | C27: Whately | D27: =_xlfn.XLOOKUP(C27,'Territory List'!$D$2:$D$352,'Territory List'!$G$2:$G$352) -> 3 | E27: =VLOOKUP(A27,'3-Sue'!$A$2:$F$22,3,FALSE) -> 46035 | F27: =VLOOKUP(A27,'3-Sue'!$A$1:$H$45,7,FALSE) -> 0 | G27: =VLOOKUP(A27,'3-Sue'!$A$2:$F$22,4,FALSE) -> - | H27: =VLOOKUP(A27,'3-Sue'!$A$2:$F$22,5,FALSE) -> - | I27: =VLOOKUP(A27,'3-Sue'!$A$2:$F$22,6,FALSE) -> - | J27: =VLOOKUP(A27,'3-Sue'!$A$1:$H$45,8,FALSE) -> 0
A28: WESTHAMPTON, TOWN OF | B28: WESTHAMPTON | C28: Westhampton | D28: =_xlfn.XLOOKUP(C28,'Territory List'!$D$2:$D$352,'Territory List'!$G$2:$G$352) -> 3 | E28: =VLOOKUP(A28,'3-Sue'!$A$2:$F$22,3,FALSE) -> 4/21 @10am | F28: =VLOOKUP(A28,'3-Sue'!$A$1:$H$45,7,FALSE) -> 10/13 @ 12pm | G28: =VLOOKUP(A28,'3-Sue'!$A$2:$F$22,4,FALSE) -> Ryan (Westhampton, Barre | H28: =VLOOKUP(A28,'3-Sue'!$A$2:$F$22,5,FALSE) -> - | I28: =VLOOKUP(A28,'3-Sue'!$A$2:$F$22,6,FALSE) -> - | J28: =VLOOKUP(A28,'3-Sue'!$A$1:$H$45,8,FALSE) -> 0
A29: SUNDERLAND, TOWN OF | B29: SUNDERLAND | C29: Sunderland | D29: =_xlfn.XLOOKUP(C29,'Territory List'!$D$2:$D$352,'Territory List'!$G$2:$G$352) -> 3 | E29: =VLOOKUP(A29,'3-Sue'!$A$2:$F$22,3,FALSE) -> 5/19 @ 11am | F29: =VLOOKUP(A29,'3-Sue'!$A$1:$H$45,7,FALSE) -> 0 | G29: =VLOOKUP(A29,'3-Sue'!$A$2:$F$22,4,FALSE) -> - | H29: =VLOOKUP(A29,'3-Sue'!$A$2:$F$22,5,FALSE) -> - | J29: =VLOOKUP(A29,'3-Sue'!$A$1:$H$45,8,FALSE) -> 0
A30: SPRINGFIELD WATER AND SEWER COMMISSION | B30: AGAWAM | C30: Agawam | D30: =_xlfn.XLOOKUP(C30,'Territory List'!$D$2:$D$352,'Territory List'!$G$2:$G$352) -> 3 | E30: =VLOOKUP(A30,'3-Sue'!$A$2:$F$22,3,FALSE) -> 46195.479 | F30: =VLOOKUP(A30,'3-Sue'!$A$1:$H$45,7,FALSE) -> 0 | G30: =VLOOKUP(A30,'3-Sue'!$A$2:$F$22,4,FALSE) -> Once a year/annual meeting* | H30: =VLOOKUP(A30,'3-Sue'!$A$2:$F$22,5,FALSE) -> 10 CY-3 FY | I30: =VLOOKUP(A30,'3-Sue'!$A$2:$F$22,6,FALSE) -> 2 advisors | J30: =VLOOKUP(A30,'3-Sue'!$A$1:$H$45,8,FALSE) -> 1
A31: SOUTHWICK, TOWN OF | B31: SOUTHWICK | C31: Southwick | D31: =_xlfn.XLOOKUP(C31,'Territory List'!$D$2:$D$352,'Territory List'!$G$2:$G$352) -> 3 | E31: =VLOOKUP(A31,'3-Sue'!$A$2:$F$22,3,FALSE) -> 3/19/2026 @ 10:00 | F31: =VLOOKUP(A31,'3-Sue'!$A$1:$H$45,7,FALSE) -> 0 | G31: =VLOOKUP(A31,'3-Sue'!$A$2:$F$22,4,FALSE) -> Annual review with committee | H31: =VLOOKUP(A31,'3-Sue'!$A$2:$F$22,5,FALSE) -> 20 | I31: =VLOOKUP(A31,'3-Sue'!$A$2:$F$22,6,FALSE) -> - | J31: =VLOOKUP(A31,'3-Sue'!$A$1:$H$45,8,FALSE) -> 0
A32: SOUTHAMPTON, TOWN OF | B32: SOUTHAMPTON | C32: Southampton | D32: =_xlfn.XLOOKUP(C32,'Territory List'!$D$2:$D$352,'Territory List'!$G$2:$G$352) -> 3 | E32: =VLOOKUP(A32,'3-Sue'!$A$2:$F$22,3,FALSE) -> Sent material | F32: =VLOOKUP(A32,'3-Sue'!$A$1:$H$45,7,FALSE) -> 0 | G32: =VLOOKUP(A32,'3-Sue'!$A$2:$F$22,4,FALSE) -> - | H32: =VLOOKUP(A32,'3-Sue'!$A$2:$F$22,5,FALSE) -> - | I32: =VLOOKUP(A32,'3-Sue'!$A$2:$F$22,6,FALSE) -> - | J32: =VLOOKUP(A32,'3-Sue'!$A$1:$H$45,8,FALSE) -> 0
A33: SOUTH HADLEY, TOWN OF | B33: SOUTH HADLEY | C33: South Hadley | D33: =_xlfn.XLOOKUP(C33,'Territory List'!$D$2:$D$352,'Territory List'!$G$2:$G$352) -> 3 | E33: =VLOOKUP(A33,'3-Sue'!$A$2:$F$22,3,FALSE) -> 46051 | F33: =VLOOKUP(A33,'3-Sue'!$A$1:$H$45,7,FALSE) -> 0 | G33: =VLOOKUP(A33,'3-Sue'!$A$2:$F$22,4,FALSE) -> Donna and Lisa (TA) (Lunch only with Donna) | H33: =VLOOKUP(A33,'3-Sue'!$A$2:$F$22,5,FALSE) -> - | I33: =VLOOKUP(A33,'3-Sue'!$A$2:$F$22,6,FALSE) -> - | J33: =VLOOKUP(A33,'3-Sue'!$A$1:$H$45,8,FALSE) -> 0
A34: SOUTH HADLEY FIRE DISTRICT #1 | B34: SOUTH HADLEY | C34: South Hadley | D34: =_xlfn.XLOOKUP(C34,'Territory List'!$D$2:$D$352,'Territory List'!$G$2:$G$352) -> 3 | E34: =VLOOKUP(A34,'3-Sue'!$A$2:$F$22,3,FALSE) -> 4/30 @ 11am | F34: =VLOOKUP(A34,'3-Sue'!$A$1:$H$45,7,FALSE) -> 0 | G34: =VLOOKUP(A34,'3-Sue'!$A$2:$F$22,4,FALSE) -> For annual review invite committee** | H34: =VLOOKUP(A34,'3-Sue'!$A$2:$F$22,5,FALSE) -> - | I34: =VLOOKUP(A34,'3-Sue'!$A$2:$F$22,6,FALSE) -> - | J34: =VLOOKUP(A34,'3-Sue'!$A$1:$H$45,8,FALSE) -> 0
A35: NORTHAMPTON, CITY OF | B35: NORTHAMPTON | C35: Northampton | D35: =_xlfn.XLOOKUP(C35,'Territory List'!$D$2:$D$352,'Territory List'!$G$2:$G$352) -> 3 | E35: =VLOOKUP(A35,'3-Sue'!$A$2:$F$22,3,FALSE) -> - | F35: =VLOOKUP(A35,'3-Sue'!$A$1:$H$45,7,FALSE) -> 0 | G35: =VLOOKUP(A35,'3-Sue'!$A$2:$F$22,4,FALSE) -> Meet with Trust Comm once year | H35: =VLOOKUP(A35,'3-Sue'!$A$2:$F$22,5,FALSE) -> - | I35: =VLOOKUP(A35,'3-Sue'!$A$2:$F$22,6,FALSE) -> - | J35: =VLOOKUP(A35,'3-Sue'!$A$1:$H$45,8,FALSE) -> 0
A36: HIGHLAND VALLEY ELDER SERVICES | B36: NORTHAMPTON | C36: Northampton | D36: =_xlfn.XLOOKUP(C36,'Territory List'!$D$2:$D$352,'Territory List'!$G$2:$G$352) -> 3 | E36: =VLOOKUP(A36,'3-Sue'!$A$2:$F$22,3,FALSE) -> 5/4 @ 3pm virtual | F36: =VLOOKUP(A36,'3-Sue'!$A$1:$H$45,7,FALSE) -> 0 | G36: =VLOOKUP(A36,'3-Sue'!$A$2:$F$22,4,FALSE) -> - | H36: =VLOOKUP(A36,'3-Sue'!$A$2:$F$22,5,FALSE) -> - | I36: =VLOOKUP(A36,'3-Sue'!$A$2:$F$22,6,FALSE) -> 2 advisors | J36: =VLOOKUP(A36,'3-Sue'!$A$1:$H$45,8,FALSE) -> 0
A37: HATFIELD, TOWN OF | B37: HATFIELD | C37: Hatfield | D37: =_xlfn.XLOOKUP(C37,'Territory List'!$D$2:$D$352,'Territory List'!$G$2:$G$352) -> 3 | E37: =VLOOKUP(A37,'3-Sue'!$A$2:$F$22,3,FALSE) -> 5/19 @ 9:30 | F37: =VLOOKUP(A37,'3-Sue'!$A$1:$H$45,7,FALSE) -> 9/15 @ 10am | G37: =VLOOKUP(A37,'3-Sue'!$A$2:$F$22,4,FALSE) -> - | H37: =VLOOKUP(A37,'3-Sue'!$A$2:$F$22,5,FALSE) -> - | I37: =VLOOKUP(A37,'3-Sue'!$A$2:$F$22,6,FALSE) -> - | J37: =VLOOKUP(A37,'3-Sue'!$A$1:$H$45,8,FALSE) -> 0
A38: HADLEY, TOWN OF | B38: HADLEY | C38: Hadley | D38: =_xlfn.XLOOKUP(C38,'Territory List'!$D$2:$D$352,'Territory List'!$G$2:$G$352) -> 3 | E38: =VLOOKUP(A38,'3-Sue'!$A$2:$F$22,3,FALSE) -> Sent material | F38: =VLOOKUP(A38,'3-Sue'!$A$1:$H$45,7,FALSE) -> 0 | G38: =VLOOKUP(A38,'3-Sue'!$A$2:$F$22,4,FALSE) -> - | H38: =VLOOKUP(A38,'3-Sue'!$A$2:$F$22,5,FALSE) -> - | I38: =VLOOKUP(A38,'3-Sue'!$A$2:$F$22,6,FALSE) -> - | J38: =VLOOKUP(A38,'3-Sue'!$A$1:$H$45,8,FALSE) -> 0
A39: FRIENDS OF FORBES LIBRARY | B39: NORTHAMPTON | C39: Northampton | D39: =_xlfn.XLOOKUP(C39,'Territory List'!$D$2:$D$352,'Territory List'!$G$2:$G$352) -> 3 | E39: =VLOOKUP(A39,'3-Sue'!$A$2:$F$22,3,FALSE) -> - | F39: =VLOOKUP(A39,'3-Sue'!$A$1:$H$45,7,FALSE) -> 0 | G39: =VLOOKUP(A39,'3-Sue'!$A$2:$F$22,4,FALSE) -> No Acct. rpt./Meet annually | H39: =VLOOKUP(A39,'3-Sue'!$A$2:$F$22,5,FALSE) -> 14 | I39: =VLOOKUP(A39,'3-Sue'!$A$2:$F$22,6,FALSE) -> 2 advisors | J39: =VLOOKUP(A39,'3-Sue'!$A$1:$H$45,8,FALSE) -> 0
A40: FORBES LIBRARY | B40: NORTHAMPTON | C40: Northampton | D40: =_xlfn.XLOOKUP(C40,'Territory List'!$D$2:$D$352,'Territory List'!$G$2:$G$352) -> 3 | E40: =VLOOKUP(A40,'3-Sue'!$A$2:$F$22,3,FALSE) -> 46076 | F40: =VLOOKUP(A40,'3-Sue'!$A$1:$H$45,7,FALSE) -> 0 | G40: =VLOOKUP(A40,'3-Sue'!$A$2:$F$22,4,FALSE) -> - | H40: =VLOOKUP(A40,'3-Sue'!$A$2:$F$22,5,FALSE) -> 13 | I40: =VLOOKUP(A40,'3-Sue'!$A$2:$F$22,6,FALSE) -> Kathleen | J40: =VLOOKUP(A40,'3-Sue'!$A$1:$H$45,8,FALSE) -> 0
...

Sheet Territory List
A1: Client Count | B1: Client | C1: Prospect | D1: Cities and Towns | E1: Municipal_Type | F1: County | G1: Subregion | H1: CLIENT NAME 1 | I1: CLIENT NAME 2 | J1: CLIENT NAME 3 | K1: CLIENT NAME 4 | L1: CLIENT NAME 5 | M1: CLIENT NAME 6 | N1: CLIENT NAME 7
B2: {=IF(SUM(COUNTIF($H2:$N2,{"*TOWN OF*","*CITY OF*"}))>0,"✓","")} | C2: =IF(AND($B2="",COUNTA($H2:$N2)>0),"✓","") -> ✓ | D2: Alford | E2: Town | F2: Berkshire | G2: 1 | H2: {=IFERROR( _xlfn.LET( _xlpm.clean, _xlfn.LAMBDA(_xlpm.x, TRIM(SUBSTITUTE(_xlpm.x,CHAR(160)," "))), _xlpm.t, CLEAN($D2), _xlpm.data, _xlfn._xlws.FILTER( CHOOSE({1,2}, 'DO NOT EDIT - Client List'!$A$2:$A$346, 'DO NOT EDIT - Client List'!$E$2:$E$346), CLEAN('DO NOT EDIT - Client List'!$C$2:$C$346)=_xlpm.t ), _xlpm.k, _xlfn.SEQUENCE(6), _xlpm.nm, IFERROR(INDEX(_xlpm.data, _xlpm.k, 1), ""), _xlpm.dt_raw, IFERROR(INDEX(_xlpm.data, _xlpm.k, 2), ""), _xlpm.dt_num, IF( ISNUMBER(_xlpm.dt_raw), _xlpm.dt_raw, IFERROR(DATEVALUE(_xlpm.dt_raw), 0) ), TRANSPOSE( IF(_xlpm.nm="","", _xlpm.nm & IF(_xlpm.dt_num=0, "", " - " & TEXT(_xlpm.dt_num,"m/d/yyyy")) ) ) ), "")}
B3: {=IF(SUM(COUNTIF($H3:$N3,{"*TOWN OF*","*CITY OF*"}))>0,"✓","")} -> ✓ | C3: =IF(AND($B3="",COUNTA($H3:$N3)>0),"✓","") | D3: Becket | E3: Town | F3: Berkshire | G3: 1 | H3: {=IFERROR( _xlfn.LET( _xlpm.clean, _xlfn.LAMBDA(_xlpm.x, TRIM(SUBSTITUTE(_xlpm.x,CHAR(160)," "))), _xlpm.t, CLEAN($D3), _xlpm.data, _xlfn._xlws.FILTER( CHOOSE({1,2}, 'DO NOT EDIT - Client List'!$A$2:$A$346, 'DO NOT EDIT - Client List'!$E$2:$E$346), CLEAN('DO NOT EDIT - Client List'!$C$2:$C$346)=_xlpm.t ), _xlpm.k, _xlfn.SEQUENCE(6), _xlpm.nm, IFERROR(INDEX(_xlpm.data, _xlpm.k, 1), ""), _xlpm.dt_raw, IFERROR(INDEX(_xlpm.data, _xlpm.k, 2), ""), _xlpm.dt_num, IF( ISNUMBER(_xlpm.dt_raw), _xlpm.dt_raw, IFERROR(DATEVALUE(_xlpm.dt_raw), 0) ), TRANSPOSE( IF(_xlpm.nm="","", _xlpm.nm & IF(_xlpm.dt_num=0, "", " - " & TEXT(_xlpm.dt_num,"m/d/yyyy")) ) ) ), "")} -> BECKET, TOWN OF - 1/15/2026 | I3: BECKET BROADBAND DISTRICT - 1/15/2026
B4: {=IF(SUM(COUNTIF($H4:$N4,{"*TOWN OF*","*CITY OF*"}))>0,"✓","")} -> ✓ | C4: =IF(AND($B4="",COUNTA($H4:$N4)>0),"✓","") | D4: Blandford | E4: Town | F4: Hampden | G4: 1 | H4: {=IFERROR( _xlfn.LET( _xlpm.clean, _xlfn.LAMBDA(_xlpm.x, TRIM(SUBSTITUTE(_xlpm.x,CHAR(160)," "))), _xlpm.t, CLEAN($D4), _xlpm.data, _xlfn._xlws.FILTER( CHOOSE({1,2}, 'DO NOT EDIT - Client List'!$A$2:$A$346, 'DO NOT EDIT - Client List'!$E$2:$E$346), CLEAN('DO NOT EDIT - Client List'!$C$2:$C$346)=_xlpm.t ), _xlpm.k, _xlfn.SEQUENCE(6), _xlpm.nm, IFERROR(INDEX(_xlpm.data, _xlpm.k, 1), ""), _xlpm.dt_raw, IFERROR(INDEX(_xlpm.data, _xlpm.k, 2), ""), _xlpm.dt_num, IF( ISNUMBER(_xlpm.dt_raw), _xlpm.dt_raw, IFERROR(DATEVALUE(_xlpm.dt_raw), 0) ), TRANSPOSE( IF(_xlpm.nm="","", _xlpm.nm & IF(_xlpm.dt_num=0, "", " - " & TEXT(_xlpm.dt_num,"m/d/yyyy")) ) ) ), "")} -> BLANDFORD, TOWN OF - 12/10/2025
B5: {=IF(SUM(COUNTIF($H5:$N5,{"*TOWN OF*","*CITY OF*"}))>0,"✓","")} -> ✓ | C5: =IF(AND($B5="",COUNTA($H5:$N5)>0),"✓","") | D5: Chester | E5: Town | F5: Hampden | G5: 1 | H5: {=IFERROR( _xlfn.LET( _xlpm.clean, _xlfn.LAMBDA(_xlpm.x, TRIM(SUBSTITUTE(_xlpm.x,CHAR(160)," "))), _xlpm.t, CLEAN($D5), _xlpm.data, _xlfn._xlws.FILTER( CHOOSE({1,2}, 'DO NOT EDIT - Client List'!$A$2:$A$346, 'DO NOT EDIT - Client List'!$E$2:$E$346), CLEAN('DO NOT EDIT - Client List'!$C$2:$C$346)=_xlpm.t ), _xlpm.k, _xlfn.SEQUENCE(6), _xlpm.nm, IFERROR(INDEX(_xlpm.data, _xlpm.k, 1), ""), _xlpm.dt_raw, IFERROR(INDEX(_xlpm.data, _xlpm.k, 2), ""), _xlpm.dt_num, IF( ISNUMBER(_xlpm.dt_raw), _xlpm.dt_raw, IFERROR(DATEVALUE(_xlpm.dt_raw), 0) ), TRANSPOSE( IF(_xlpm.nm="","", _xlpm.nm & IF(_xlpm.dt_num=0, "", " - " & TEXT(_xlpm.dt_num,"m/d/yyyy")) ) ) ), "")} -> CHESTER, TOWN OF - 12/10/2025
B6: {=IF(SUM(COUNTIF($H6:$N6,{"*TOWN OF*","*CITY OF*"}))>0,"✓","")} -> ✓ | C6: =IF(AND($B6="",COUNTA($H6:$N6)>0),"✓","") | D6: Egremont | E6: Town | F6: Berkshire | G6: 1 | H6: {=IFERROR( _xlfn.LET( _xlpm.clean, _xlfn.LAMBDA(_xlpm.x, TRIM(SUBSTITUTE(_xlpm.x,CHAR(160)," "))), _xlpm.t, CLEAN($D6), _xlpm.data, _xlfn._xlws.FILTER( CHOOSE({1,2}, 'DO NOT EDIT - Client List'!$A$2:$A$346, 'DO NOT EDIT - Client List'!$E$2:$E$346), CLEAN('DO NOT EDIT - Client List'!$C$2:$C$346)=_xlpm.t ), _xlpm.k, _xlfn.SEQUENCE(6), _xlpm.nm, IFERROR(INDEX(_xlpm.data, _xlpm.k, 1), ""), _xlpm.dt_raw, IFERROR(INDEX(_xlpm.data, _xlpm.k, 2), ""), _xlpm.dt_num, IF( ISNUMBER(_xlpm.dt_raw), _xlpm.dt_raw, IFERROR(DATEVALUE(_xlpm.dt_raw), 0) ), TRANSPOSE( IF(_xlpm.nm="","", _xlpm.nm & IF(_xlpm.dt_num=0, "", " - " & TEXT(_xlpm.dt_num,"m/d/yyyy")) ) ) ), "")} -> EGREMONT, TOWN OF - 3/23/2025
B7: {=IF(SUM(COUNTIF($H7:$N7,{"*TOWN OF*","*CITY OF*"}))>0,"✓","")} | C7: =IF(AND($B7="",COUNTA($H7:$N7)>0),"✓","") -> ✓ | D7: Granville | E7: Town | F7: Hampden | G7: 1 | H7: {=IFERROR( _xlfn.LET( _xlpm.clean, _xlfn.LAMBDA(_xlpm.x, TRIM(SUBSTITUTE(_xlpm.x,CHAR(160)," "))), _xlpm.t, CLEAN($D7), _xlpm.data, _xlfn._xlws.FILTER( CHOOSE({1,2}, 'DO NOT EDIT - Client List'!$A$2:$A$346, 'DO NOT EDIT - Client List'!$E$2:$E$346), CLEAN('DO NOT EDIT - Client List'!$C$2:$C$346)=_xlpm.t ), _xlpm.k, _xlfn.SEQUENCE(6), _xlpm.nm, IFERROR(INDEX(_xlpm.data, _xlpm.k, 1), ""), _xlpm.dt_raw, IFERROR(INDEX(_xlpm.data, _xlpm.k, 2), ""), _xlpm.dt_num, IF( ISNUMBER(_xlpm.dt_raw), _xlpm.dt_raw, IFERROR(DATEVALUE(_xlpm.dt_raw), 0) ), TRANSPOSE( IF(_xlpm.nm="","", _xlpm.nm & IF(_xlpm.dt_num=0, "", " - " & TEXT(_xlpm.dt_num,"m/d/yyyy")) ) ) ), "")}
B8: {=IF(SUM(COUNTIF($H8:$N8,{"*TOWN OF*","*CITY OF*"}))>0,"✓","")} -> ✓ | C8: =IF(AND($B8="",COUNTA($H8:$N8)>0),"✓","") | D8: Great Barrington | E8: Town | F8: Berkshire | G8: 1 | H8: {=IFERROR( _xlfn.LET( _xlpm.clean, _xlfn.LAMBDA(_xlpm.x, TRIM(SUBSTITUTE(_xlpm.x,CHAR(160)," "))), _xlpm.t, CLEAN($D8), _xlpm.data, _xlfn._xlws.FILTER( CHOOSE({1,2}, 'DO NOT EDIT - Client List'!$A$2:$A$346, 'DO NOT EDIT - Client List'!$E$2:$E$346), CLEAN('DO NOT EDIT - Client List'!$C$2:$C$346)=_xlpm.t ), _xlpm.k, _xlfn.SEQUENCE(6), _xlpm.nm, IFERROR(INDEX(_xlpm.data, _xlpm.k, 1), ""), _xlpm.dt_raw, IFERROR(INDEX(_xlpm.data, _xlpm.k, 2), ""), _xlpm.dt_num, IF( ISNUMBER(_xlpm.dt_raw), _xlpm.dt_raw, IFERROR(DATEVALUE(_xlpm.dt_raw), 0) ), TRANSPOSE( IF(_xlpm.nm="","", _xlpm.nm & IF(_xlpm.dt_num=0, "", " - " & TEXT(_xlpm.dt_num,"m/d/yyyy")) ) ) ), "")} -> GREAT BARRINGTON, TOWN OF
B9: {=IF(SUM(COUNTIF($H9:$N9,{"*TOWN OF*","*CITY OF*"}))>0,"✓","")} -> ✓ | C9: =IF(AND($B9="",COUNTA($H9:$N9)>0),"✓","") | D9: Lee | E9: Town | F9: Berkshire | G9: 1 | H9: {=IFERROR( _xlfn.LET( _xlpm.clean, _xlfn.LAMBDA(_xlpm.x, TRIM(SUBSTITUTE(_xlpm.x,CHAR(160)," "))), _xlpm.t, CLEAN($D9), _xlpm.data, _xlfn._xlws.FILTER( CHOOSE({1,2}, 'DO NOT EDIT - Client List'!$A$2:$A$346, 'DO NOT EDIT - Client List'!$E$2:$E$346), CLEAN('DO NOT EDIT - Client List'!$C$2:$C$346)=_xlpm.t ), _xlpm.k, _xlfn.SEQUENCE(6), _xlpm.nm, IFERROR(INDEX(_xlpm.data, _xlpm.k, 1), ""), _xlpm.dt_raw, IFERROR(INDEX(_xlpm.data, _xlpm.k, 2), ""), _xlpm.dt_num, IF( ISNUMBER(_xlpm.dt_raw), _xlpm.dt_raw, IFERROR(DATEVALUE(_xlpm.dt_raw), 0) ), TRANSPOSE( IF(_xlpm.nm="","", _xlpm.nm & IF(_xlpm.dt_num=0, "", " - " & TEXT(_xlpm.dt_num,"m/d/yyyy")) ) ) ), "")} -> LEE, TOWN OF
B10: {=IF(SUM(COUNTIF($H10:$N10,{"*TOWN OF*","*CITY OF*"}))>0,"✓","")} -> ✓ | C10: =IF(AND($B10="",COUNTA($H10:$N10)>0),"✓","") | D10: Lenox | E10: Town | F10: Berkshire | G10: 1 | H10: {=IFERROR( _xlfn.LET( _xlpm.clean, _xlfn.LAMBDA(_xlpm.x, TRIM(SUBSTITUTE(_xlpm.x,CHAR(160)," "))), _xlpm.t, CLEAN($D10), _xlpm.data, _xlfn._xlws.FILTER( CHOOSE({1,2}, 'DO NOT EDIT - Client List'!$A$2:$A$346, 'DO NOT EDIT - Client List'!$E$2:$E$346), CLEAN('DO NOT EDIT - Client List'!$C$2:$C$346)=_xlpm.t ), _xlpm.k, _xlfn.SEQUENCE(6), _xlpm.nm, IFERROR(INDEX(_xlpm.data, _xlpm.k, 1), ""), _xlpm.dt_raw, IFERROR(INDEX(_xlpm.data, _xlpm.k, 2), ""), _xlpm.dt_num, IF( ISNUMBER(_xlpm.dt_raw), _xlpm.dt_raw, IFERROR(DATEVALUE(_xlpm.dt_raw), 0) ), TRANSPOSE( IF(_xlpm.nm="","", _xlpm.nm & IF(_xlpm.dt_num=0, "", " - " & TEXT(_xlpm.dt_num,"m/d/yyyy")) ) ) ), "")} -> LENOX, TOWN OF
B11: {=IF(SUM(COUNTIF($H11:$N11,{"*TOWN OF*","*CITY OF*"}))>0,"✓","")} -> ✓ | C11: =IF(AND($B11="",COUNTA($H11:$N11)>0),"✓","") | D11: Monterey | E11: Town | F11: Berkshire | G11: 1 | H11: {=IFERROR( _xlfn.LET( _xlpm.clean, _xlfn.LAMBDA(_xlpm.x, TRIM(SUBSTITUTE(_xlpm.x,CHAR(160)," "))), _xlpm.t, CLEAN($D11), _xlpm.data, _xlfn._xlws.FILTER( CHOOSE({1,2}, 'DO NOT EDIT - Client List'!$A$2:$A$346, 'DO NOT EDIT - Client List'!$E$2:$E$346), CLEAN('DO NOT EDIT - Client List'!$C$2:$C$346)=_xlpm.t ), _xlpm.k, _xlfn.SEQUENCE(6), _xlpm.nm, IFERROR(INDEX(_xlpm.data, _xlpm.k, 1), ""), _xlpm.dt_raw, IFERROR(INDEX(_xlpm.data, _xlpm.k, 2), ""), _xlpm.dt_num, IF( ISNUMBER(_xlpm.dt_raw), _xlpm.dt_raw, IFERROR(DATEVALUE(_xlpm.dt_raw), 0) ), TRANSPOSE( IF(_xlpm.nm="","", _xlpm.nm & IF(_xlpm.dt_num=0, "", " - " & TEXT(_xlpm.dt_num,"m/d/yyyy")) ) ) ), "")} -> MONTEREY, TOWN OF
B12: {=IF(SUM(COUNTIF($H12:$N12,{"*TOWN OF*","*CITY OF*"}))>0,"✓","")} | C12: =IF(AND($B12="",COUNTA($H12:$N12)>0),"✓","") -> ✓ | D12: Mount Washington | E12: Town | F12: Berkshire | G12: 1 | H12: {=IFERROR( _xlfn.LET( _xlpm.clean, _xlfn.LAMBDA(_xlpm.x, TRIM(SUBSTITUTE(_xlpm.x,CHAR(160)," "))), _xlpm.t, CLEAN($D12), _xlpm.data, _xlfn._xlws.FILTER( CHOOSE({1,2}, 'DO NOT EDIT - Client List'!$A$2:$A$346, 'DO NOT EDIT - Client List'!$E$2:$E$346), CLEAN('DO NOT EDIT - Client List'!$C$2:$C$346)=_xlpm.t ), _xlpm.k, _xlfn.SEQUENCE(6), _xlpm.nm, IFERROR(INDEX(_xlpm.data, _xlpm.k, 1), ""), _xlpm.dt_raw, IFERROR(INDEX(_xlpm.data, _xlpm.k, 2), ""), _xlpm.dt_num, IF( ISNUMBER(_xlpm.dt_raw), _xlpm.dt_raw, IFERROR(DATEVALUE(_xlpm.dt_raw), 0) ), TRANSPOSE( IF(_xlpm.nm="","", _xlpm.nm & IF(_xlpm.dt_num=0, "", " - " & TEXT(_xlpm.dt_num,"m/d/yyyy")) ) ) ), "")}
B13: {=IF(SUM(COUNTIF($H13:$N13,{"*TOWN OF*","*CITY OF*"}))>0,"✓","")} | C13: =IF(AND($B13="",COUNTA($H13:$N13)>0),"✓","") -> ✓ | D13: New Marlborough | E13: Town | F13: Berkshire | G13: 1 | H13: {=IFERROR( _xlfn.LET( _xlpm.clean, _xlfn.LAMBDA(_xlpm.x, TRIM(SUBSTITUTE(_xlpm.x,CHAR(160)," "))), _xlpm.t, CLEAN($D13), _xlpm.data, _xlfn._xlws.FILTER( CHOOSE({1,2}, 'DO NOT EDIT - Client List'!$A$2:$A$346, 'DO NOT EDIT - Client List'!$E$2:$E$346), CLEAN('DO NOT EDIT - Client List'!$C$2:$C$346)=_xlpm.t ), _xlpm.k, _xlfn.SEQUENCE(6), _xlpm.nm, IFERROR(INDEX(_xlpm.data, _xlpm.k, 1), ""), _xlpm.dt_raw, IFERROR(INDEX(_xlpm.data, _xlpm.k, 2), ""), _xlpm.dt_num, IF( ISNUMBER(_xlpm.dt_raw), _xlpm.dt_raw, IFERROR(DATEVALUE(_xlpm.dt_raw), 0) ), TRANSPOSE( IF(_xlpm.nm="","", _xlpm.nm & IF(_xlpm.dt_num=0, "", " - " & TEXT(_xlpm.dt_num,"m/d/yyyy")) ) ) ), "")} -> LAKE BUEL PRESERVATION DISTRICT
B14: {=IF(SUM(COUNTIF($H14:$N14,{"*TOWN OF*","*CITY OF*"}))>0,"✓","")} -> ✓ | C14: =IF(AND($B14="",COUNTA($H14:$N14)>0),"✓","") | D14: Otis | E14: Town | F14: Berkshire | G14: 1 | H14: {=IFERROR( _xlfn.LET( _xlpm.clean, _xlfn.LAMBDA(_xlpm.x, TRIM(SUBSTITUTE(_xlpm.x,CHAR(160)," "))), _xlpm.t, CLEAN($D14), _xlpm.data, _xlfn._xlws.FILTER( CHOOSE({1,2}, 'DO NOT EDIT - Client List'!$A$2:$A$346, 'DO NOT EDIT - Client List'!$E$2:$E$346), CLEAN('DO NOT EDIT - Client List'!$C$2:$C$346)=_xlpm.t ), _xlpm.k, _xlfn.SEQUENCE(6), _xlpm.nm, IFERROR(INDEX(_xlpm.data, _xlpm.k, 1), ""), _xlpm.dt_raw, IFERROR(INDEX(_xlpm.data, _xlpm.k, 2), ""), _xlpm.dt_num, IF( ISNUMBER(_xlpm.dt_raw), _xlpm.dt_raw, IFERROR(DATEVALUE(_xlpm.dt_raw), 0) ), TRANSPOSE( IF(_xlpm.nm="","", _xlpm.nm & IF(_xlpm.dt_num=0, "", " - " & TEXT(_xlpm.dt_num,"m/d/yyyy")) ) ) ), "")} -> OTIS, TOWN OF
B15: {=IF(SUM(COUNTIF($H15:$N15,{"*TOWN OF*","*CITY OF*"}))>0,"✓","")} -> ✓ | C15: =IF(AND($B15="",COUNTA($H15:$N15)>0),"✓","") | D15: Richmond | E15: Town | F15: Berkshire | G15: 1 | H15: {=IFERROR( _xlfn.LET( _xlpm.clean, _xlfn.LAMBDA(_xlpm.x, TRIM(SUBSTITUTE(_xlpm.x,CHAR(160)," "))), _xlpm.t, CLEAN($D15), _xlpm.data, _xlfn._xlws.FILTER( CHOOSE({1,2}, 'DO NOT EDIT - Client List'!$A$2:$A$346, 'DO NOT EDIT - Client List'!$E$2:$E$346), CLEAN('DO NOT EDIT - Client List'!$C$2:$C$346)=_xlpm.t ), _xlpm.k, _xlfn.SEQUENCE(6), _xlpm.nm, IFERROR(INDEX(_xlpm.data, _xlpm.k, 1), ""), _xlpm.dt_raw, IFERROR(INDEX(_xlpm.data, _xlpm.k, 2), ""), _xlpm.dt_num, IF( ISNUMBER(_xlpm.dt_raw), _xlpm.dt_raw, IFERROR(DATEVALUE(_xlpm.dt_raw), 0) ), TRANSPOSE( IF(_xlpm.nm="","", _xlpm.nm & IF(_xlpm.dt_num=0, "", " - " & TEXT(_xlpm.dt_num,"m/d/yyyy")) ) ) ), "")} -> RICHMOND, TOWN OF
... B37: {=IF(SUM(COUNTIF($H37:$N37,{"*TOWN OF*","*CITY OF*"}))>0,"✓","")} | C37: =IF(AND($B37="",COUNTA($H37:$N37)>0),"✓","") -> ✓ | D37: Hinsdale | E37: Town | F37: Berkshire | G37: 2 | H37: {=IFERROR( _xlfn.LET( _xlpm.clean, _xlfn.LAMBDA(_xlpm.x, TRIM(SUBSTITUTE(_xlpm.x,CHAR(160)," "))), _xlpm.t, CLEAN($D37), _xlpm.data, _xlfn._xlws.FILTER( CHOOSE({1,2}, 'DO NOT EDIT - Client List'!$A$2:$A$346, 'DO NOT EDIT - Client List'!$E$2:$E$346), CLEAN('DO NOT EDIT - Client List'!$C$2:$C$346)=_xlpm.t ), _xlpm.k, _xlfn.SEQUENCE(6), _xlpm.nm, IFERROR(INDEX(_xlpm.data, _xlpm.k, 1), ""), _xlpm.dt_raw, IFERROR(INDEX(_xlpm.data, _xlpm.k, 2), ""), _xlpm.dt_num, IF( ISNUMBER(_xlpm.dt_raw), _xlpm.dt_raw, IFERROR(DATEVALUE(_xlpm.dt_raw), 0) ), TRANSPOSE( IF(_xlpm.nm="","", _xlpm.nm & IF(_xlpm.dt_num=0, "", " - " & TEXT(_xlpm.dt_num,"m/d/yyyy")) ) ) ), "")}
B38: {=IF(SUM(COUNTIF($H38:$N38,{"*TOWN OF*","*CITY OF*"}))>0,"✓","")} -> ✓ | C38: =IF(AND($B38="",COUNTA($H38:$N38)>0),"✓","") | D38: Lanesborough | E38: Town | F38: Berkshire | G38: 2 | H38: {=IFERROR( _xlfn.LET( _xlpm.clean, _xlfn.LAMBDA(_xlpm.x, TRIM(SUBSTITUTE(_xlpm.x,CHAR(160)," "))), _xlpm.t, CLEAN($D38), _xlpm.data, _xlfn._xlws.FILTER( CHOOSE({1,2}, 'DO NOT EDIT - Client List'!$A$2:$A$346, 'DO NOT EDIT - Client List'!$E$2:$E$346), CLEAN('DO NOT EDIT - Client List'!$C$2:$C$346)=_xlpm.t ), _xlpm.k, _xlfn.SEQUENCE(6), _xlpm.nm, IFERROR(INDEX(_xlpm.data, _xlpm.k, 1), ""), _xlpm.dt_raw, IFERROR(INDEX(_xlpm.data, _xlpm.k, 2), ""), _xlpm.dt_num, IF( ISNUMBER(_xlpm.dt_raw), _xlpm.dt_raw, IFERROR(DATEVALUE(_xlpm.dt_raw), 0) ), TRANSPOSE( IF(_xlpm.nm="","", _xlpm.nm & IF(_xlpm.dt_num=0, "", " - " & TEXT(_xlpm.dt_num,"m/d/yyyy")) ) ) ), "")} -> LANESBOROUGH, TOWN OF | I38: LANESBOROUGH VILLAGE FIRE & WATER DISTRICT
B39: {=IF(SUM(COUNTIF($H39:$N39,{"*TOWN OF*","*CITY OF*"}))>0,"✓","")} | C39: =IF(AND($B39="",COUNTA($H39:$N39)>0),"✓","") -> ✓ | D39: New Ashford | E39: Town | F39: Berkshire | G39: 2 | H39: {=IFERROR( _xlfn.LET( _xlpm.clean, _xlfn.LAMBDA(_xlpm.x, TRIM(SUBSTITUTE(_xlpm.x,CHAR(160)," "))), _xlpm.t, CLEAN($D39), _xlpm.data, _xlfn._xlws.FILTER( CHOOSE({1,2}, 'DO NOT EDIT - Client List'!$A$2:$A$346, 'DO NOT EDIT - Client List'!$E$2:$E$346), CLEAN('DO NOT EDIT - Client List'!$C$2:$C$346)=_xlpm.t ), _xlpm.k, _xlfn.SEQUENCE(6), _xlpm.nm, IFERROR(INDEX(_xlpm.data, _xlpm.k, 1), ""), _xlpm.dt_raw, IFERROR(INDEX(_xlpm.data, _xlpm.k, 2), ""), _xlpm.dt_num, IF( ISNUMBER(_xlpm.dt_raw), _xlpm.dt_raw, IFERROR(DATEVALUE(_xlpm.dt_raw), 0) ), TRANSPOSE( IF(_xlpm.nm="","", _xlpm.nm & IF(_xlpm.dt_num=0, "", " - " & TEXT(_xlpm.dt_num,"m/d/yyyy")) ) ) ), "")}
B40: {=IF(SUM(COUNTIF($H40:$N40,{"*TOWN OF*","*CITY OF*"}))>0,"✓","")} -> ✓ | C40: =IF(AND($B40="",COUNTA($H40:$N40)>0),"✓","") | D40: North Adams | E40: City | F40: Berkshire | G40: 2 | H40: {=IFERROR( _xlfn.LET( _xlpm.clean, _xlfn.LAMBDA(_xlpm.x, TRIM(SUBSTITUTE(_xlpm.x,CHAR(160)," "))), _xlpm.t, CLEAN($D40), _xlpm.data, _xlfn._xlws.FILTER( CHOOSE({1,2}, 'DO NOT EDIT - Client List'!$A$2:$A$346, 'DO NOT EDIT - Client List'!$E$2:$E$346), CLEAN('DO NOT EDIT - Client List'!$C$2:$C$346)=_xlpm.t ), _xlpm.k, _xlfn.SEQUENCE(6), _xlpm.nm, IFERROR(INDEX(_xlpm.data, _xlpm.k, 1), ""), _xlpm.dt_raw, IFERROR(INDEX(_xlpm.data, _xlpm.k, 2), ""), _xlpm.dt_num, IF( ISNUMBER(_xlpm.dt_raw), _xlpm.dt_raw, IFERROR(DATEVALUE(_xlpm.dt_raw), 0) ), TRANSPOSE( IF(_xlpm.nm="","", _xlpm.nm & IF(_xlpm.dt_num=0, "", " - " & TEXT(_xlpm.dt_num,"m/d/yyyy")) ) ) ), "")} -> NORTH ADAMS, CITY OF - 3/18/2026
B41: {=IF(SUM(COUNTIF($H41:$N41,{"*TOWN OF*","*CITY OF*"}))>0,"✓","")} | C41: =IF(AND($B41="",COUNTA($H41:$N41)>0),"✓","") -> ✓ | D41: Peru | E41: Town | F41: Berkshire | G41: 2 | H41: {=IFERROR( _xlfn.LET( _xlpm.clean, _xlfn.LAMBDA(_xlpm.x, TRIM(SUBSTITUTE(_xlpm.x,CHAR(160)," "))), _xlpm.t, CLEAN($D41), _xlpm.data, _xlfn._xlws.FILTER( CHOOSE({1,2}, 'DO NOT EDIT - Client List'!$A$2:$A$346, 'DO NOT EDIT - Client List'!$E$2:$E$346), CLEAN('DO NOT EDIT - Client List'!$C$2:$C$346)=_xlpm.t ), _xlpm.k, _xlfn.SEQUENCE(6), _xlpm.nm, IFERROR(INDEX(_xlpm.data, _xlpm.k, 1), ""), _xlpm.dt_raw, IFERROR(INDEX(_xlpm.data, _xlpm.k, 2), ""), _xlpm.dt_num, IF( ISNUMBER(_xlpm.dt_raw), _xlpm.dt_raw, IFERROR(DATEVALUE(_xlpm.dt_raw), 0) ), TRANSPOSE( IF(_xlpm.nm="","", _xlpm.nm & IF(_xlpm.dt_num=0, "", " - " & TEXT(_xlpm.dt_num,"m/d/yyyy")) ) ) ), "")}
B42: {=IF(SUM(COUNTIF($H42:$N42,{"*TOWN OF*","*CITY OF*"}))>0,"✓","")} -> ✓ | C42: =IF(AND($B42="",COUNTA($H42:$N42)>0),"✓","") | D42: Pittsfield | E42: City | F42: Berkshire | G42: 2 | H42: {=IFERROR( _xlfn.LET( _xlpm.clean, _xlfn.LAMBDA(_xlpm.x, TRIM(SUBSTITUTE(_xlpm.x,CHAR(160)," "))), _xlpm.t, CLEAN($D42), _xlpm.data, _xlfn._xlws.FILTER( CHOOSE({1,2}, 'DO NOT EDIT - Client List'!$A$2:$A$346, 'DO NOT EDIT - Client List'!$E$2:$E$346), CLEAN('DO NOT EDIT - Client List'!$C$2:$C$346)=_xlpm.t ), _xlpm.k, _xlfn.SEQUENCE(6), _xlpm.nm, IFERROR(INDEX(_xlpm.data, _xlpm.k, 1), ""), _xlpm.dt_raw, IFERROR(INDEX(_xlpm.data, _xlpm.k, 2), ""), _xlpm.dt_num, IF( ISNUMBER(_xlpm.dt_raw), _xlpm.dt_raw, IFERROR(DATEVALUE(_xlpm.dt_raw), 0) ), TRANSPOSE( IF(_xlpm.nm="","", _xlpm.nm & IF(_xlpm.dt_num=0, "", " - " & TEXT(_xlpm.dt_num,"m/d/yyyy")) ) ) ), "")} -> PITTSFIELD, CITY OF - 3/27/2026
B43: {=IF(SUM(COUNTIF($H43:$N43,{"*TOWN OF*","*CITY OF*"}))>0,"✓","")} | C43: =IF(AND($B43="",COUNTA($H43:$N43)>0),"✓","") -> ✓ | D43: Plainfield | E43: Town | F43: Hampshire | G43: 2 | H43: {=IFERROR( _xlfn.LET( _xlpm.clean, _xlfn.LAMBDA(_xlpm.x, TRIM(SUBSTITUTE(_xlpm.x,CHAR(160)," "))), _xlpm.t, CLEAN($D43), _xlpm.data, _xlfn._xlws.FILTER( CHOOSE({1,2}, 'DO NOT EDIT - Client List'!$A$2:$A$346, 'DO NOT EDIT - Client List'!$E$2:$E$346), CLEAN('DO NOT EDIT - Client List'!$C$2:$C$346)=_xlpm.t ), _xlpm.k, _xlfn.SEQUENCE(6), _xlpm.nm, IFERROR(INDEX(_xlpm.data, _xlpm.k, 1), ""), _xlpm.dt_raw, IFERROR(INDEX(_xlpm.data, _xlpm.k, 2), ""), _xlpm.dt_num, IF( ISNUMBER(_xlpm.dt_raw), _xlpm.dt_raw, IFERROR(DATEVALUE(_xlpm.dt_raw), 0) ), TRANSPOSE( IF(_xlpm.nm="","", _xlpm.nm & IF(_xlpm.dt_num=0, "", " - " & TEXT(_xlpm.dt_num,"m/d/yyyy")) ) ) ), "")}
B44: {=IF(SUM(COUNTIF($H44:$N44,{"*TOWN OF*","*CITY OF*"}))>0,"✓","")} | C44: =IF(AND($B44="",COUNTA($H44:$N44)>0),"✓","") -> ✓ | D44: Savoy | E44: Town | F44: Berkshire | G44: 2 | H44: {=IFERROR( _xlfn.LET( _xlpm.clean, _xlfn.LAMBDA(_xlpm.x, TRIM(SUBSTITUTE(_xlpm.x,CHAR(160)," "))), _xlpm.t, CLEAN($D44), _xlpm.data, _xlfn._xlws.FILTER( CHOOSE({1,2}, 'DO NOT EDIT - Client List'!$A$2:$A$346, 'DO NOT EDIT - Client List'!$E$2:$E$346), CLEAN('DO NOT EDIT - Client List'!$C$2:$C$346)=_xlpm.t ), _xlpm.k, _xlfn.SEQUENCE(6), _xlpm.nm, IFERROR(INDEX(_xlpm.data, _xlpm.k, 1), ""), _xlpm.dt_raw, IFERROR(INDEX(_xlpm.data, _xlpm.k, 2), ""), _xlpm.dt_num, IF( ISNUMBER(_xlpm.dt_raw), _xlpm.dt_raw, IFERROR(DATEVALUE(_xlpm.dt_raw), 0) ), TRANSPOSE( IF(_xlpm.nm="","", _xlpm.nm & IF(_xlpm.dt_num=0, "", " - " & TEXT(_xlpm.dt_num,"m/d/yyyy")) ) ) ), "")}
B45: {=IF(SUM(COUNTIF($H45:$N45,{"*TOWN OF*","*CITY OF*"}))>0,"✓","")} -> ✓ | C45: =IF(AND($B45="",COUNTA($H45:$N45)>0),"✓","") | D45: Williamstown | E45: Town | F45: Berkshire | G45: 2 | H45: {=IFERROR( _xlfn.LET( _xlpm.clean, _xlfn.LAMBDA(_xlpm.x, TRIM(SUBSTITUTE(_xlpm.x,CHAR(160)," "))), _xlpm.t, CLEAN($D45), _xlpm.data, _xlfn._xlws.FILTER( CHOOSE({1,2}, 'DO NOT EDIT - Client List'!$A$2:$A$346, 'DO NOT EDIT - Client List'!$E$2:$E$346), CLEAN('DO NOT EDIT - Client List'!$C$2:$C$346)=_xlpm.t ), _xlpm.k, _xlfn.SEQUENCE(6), _xlpm.nm, IFERROR(INDEX(_xlpm.data, _xlpm.k, 1), ""), _xlpm.dt_raw, IFERROR(INDEX(_xlpm.data, _xlpm.k, 2), ""), _xlpm.dt_num, IF( ISNUMBER(_xlpm.dt_raw), _xlpm.dt_raw, IFERROR(DATEVALUE(_xlpm.dt_raw), 0) ), TRANSPOSE( IF(_xlpm.nm="","", _xlpm.nm & IF(_xlpm.dt_num=0, "", " - " & TEXT(_xlpm.dt_num,"m/d/yyyy")) ) ) ), "")} -> WILLIAMSTOWN, TOWN OF
B46: {=IF(SUM(COUNTIF($H46:$N46,{"*TOWN OF*","*CITY OF*"}))>0,"✓","")} -> ✓ | C46: =IF(AND($B46="",COUNTA($H46:$N46)>0),"✓","") | D46: Windsor | E46: Town | F46: Berkshire | G46: 2 | H46: {=IFERROR( _xlfn.LET( _xlpm.clean, _xlfn.LAMBDA(_xlpm.x, TRIM(SUBSTITUTE(_xlpm.x,CHAR(160)," "))), _xlpm.t, CLEAN($D46), _xlpm.data, _xlfn._xlws.FILTER( CHOOSE({1,2}, 'DO NOT EDIT - Client List'!$A$2:$A$346, 'DO NOT EDIT - Client List'!$E$2:$E$346), CLEAN('DO NOT EDIT - Client List'!$C$2:$C$346)=_xlpm.t ), _xlpm.k, _xlfn.SEQUENCE(6), _xlpm.nm, IFERROR(INDEX(_xlpm.data, _xlpm.k, 1), ""), _xlpm.dt_raw, IFERROR(INDEX(_xlpm.data, _xlpm.k, 2), ""), _xlpm.dt_num, IF( ISNUMBER(_xlpm.dt_raw), _xlpm.dt_raw, IFERROR(DATEVALUE(_xlpm.dt_raw), 0) ), TRANSPOSE( IF(_xlpm.nm="","", _xlpm.nm & IF(_xlpm.dt_num=0, "", " - " & TEXT(_xlpm.dt_num,"m/d/yyyy")) ) ) ), "")} -> WINDSOR, TOWN OF
B47: {=IF(SUM(COUNTIF($H47:$N47,{"*TOWN OF*","*CITY OF*"}))>0,"✓","")} -> ✓ | C47: =IF(AND($B47="",COUNTA($H47:$N47)>0),"✓","") | D47: Chesterfield | E47: Town | F47: Hampshire | G47: 3 | H47: {=IFERROR( _xlfn.LET( _xlpm.clean, _xlfn.LAMBDA(_xlpm.x, TRIM(SUBSTITUTE(_xlpm.x,CHAR(160)," "))), _xlpm.t, CLEAN($D47), _xlpm.data, _xlfn._xlws.FILTER( CHOOSE({1,2}, 'DO NOT EDIT - Client List'!$A$2:$A$346, 'DO NOT EDIT - Client List'!$E$2:$E$346), CLEAN('DO NOT EDIT - Client List'!$C$2:$C$346)=_xlpm.t ), _xlpm.k, _xlfn.SEQUENCE(6), _xlpm.nm, IFERROR(INDEX(_xlpm.data, _xlpm.k, 1), ""), _xlpm.dt_raw, IFERROR(INDEX(_xlpm.data, _xlpm.k, 2), ""), _xlpm.dt_num, IF( ISNUMBER(_xlpm.dt_raw), _xlpm.dt_raw, IFERROR(DATEVALUE(_xlpm.dt_raw), 0) ), TRANSPOSE( IF(_xlpm.nm="","", _xlpm.nm & IF(_xlpm.dt_num=0, "", " - " & TEXT(_xlpm.dt_num,"m/d/yyyy")) ) ) ), "")} -> CHESTERFIELD, TOWN OF - 5/26/2026
B48: {=IF(SUM(COUNTIF($H48:$N48,{"*TOWN OF*","*CITY OF*"}))>0,"✓","")} | C48: =IF(AND($B48="",COUNTA($H48:$N48)>0),"✓","") -> ✓ | D48: Huntington | E48: Town | F48: Hampshire | G48: 3 | H48: {=IFERROR( _xlfn.LET( _xlpm.clean, _xlfn.LAMBDA(_xlpm.x, TRIM(SUBSTITUTE(_xlpm.x,CHAR(160)," "))), _xlpm.t, CLEAN($D48), _xlpm.data, _xlfn._xlws.FILTER( CHOOSE({1,2}, 'DO NOT EDIT - Client List'!$A$2:$A$346, 'DO NOT EDIT - Client List'!$E$2:$E$346), CLEAN('DO NOT EDIT - Client List'!$C$2:$C$346)=_xlpm.t ), _xlpm.k, _xlfn.SEQUENCE(6), _xlpm.nm, IFERROR(INDEX(_xlpm.data, _xlpm.k, 1), ""), _xlpm.dt_raw, IFERROR(INDEX(_xlpm.data, _xlpm.k, 2), ""), _xlpm.dt_num, IF( ISNUMBER(_xlpm.dt_raw), _xlpm.dt_raw, IFERROR(DATEVALUE(_xlpm.dt_raw), 0) ), TRANSPOSE( IF(_xlpm.nm="","", _xlpm.nm & IF(_xlpm.dt_num=0, "", " - " & TEXT(_xlpm.dt_num,"m/d/yyyy")) ) ) ), "")}
B49: {=IF(SUM(COUNTIF($H49:$N49,{"*TOWN OF*","*CITY OF*"}))>0,"✓","")} | C49: =IF(AND($B49="",COUNTA($H49:$N49)>0),"✓","") -> ✓ | D49: Montgomery | E49: Town | F49: Hampden | G49: 3 | H49: {=IFERROR( _xlfn.LET( _xlpm.clean, _xlfn.LAMBDA(_xlpm.x, TRIM(SUBSTITUTE(_xlpm.x,CHAR(160)," "))), _xlpm.t, CLEAN($D49), _xlpm.data, _xlfn._xlws.FILTER( CHOOSE({1,2}, 'DO NOT EDIT - Client List'!$A$2:$A$346, 'DO NOT EDIT - Client List'!$E$2:$E$346), CLEAN('DO NOT EDIT - Client List'!$C$2:$C$346)=_xlpm.t ), _xlpm.k, _xlfn.SEQUENCE(6), _xlpm.nm, IFERROR(INDEX(_xlpm.data, _xlpm.k, 1), ""), _xlpm.dt_raw, IFERROR(INDEX(_xlpm.data, _xlpm.k, 2), ""), _xlpm.dt_num, IF( ISNUMBER(_xlpm.dt_raw), _xlpm.dt_raw, IFERROR(DATEVALUE(_xlpm.dt_raw), 0) ), TRANSPOSE( IF(_xlpm.nm="","", _xlpm.nm & IF(_xlpm.dt_num=0, "", " - " & TEXT(_xlpm.dt_num,"m/d/yyyy")) ) ) ), "")}
B50: {=IF(SUM(COUNTIF($H50:$N50,{"*TOWN OF*","*CITY OF*"}))>0,"✓","")} -> ✓ | C50: =IF(AND($B50="",COUNTA($H50:$N50)>0),"✓","") | D50: Agawam | E50: City | F50: Hampden | G50: 3 | H50: {=IFERROR( _xlfn.LET( _xlpm.clean, _xlfn.LAMBDA(_xlpm.x, TRIM(SUBSTITUTE(_xlpm.x,CHAR(160)," "))), _xlpm.t, CLEAN($D50), _xlpm.data, _xlfn._xlws.FILTER( CHOOSE({1,2}, 'DO NOT EDIT - Client List'!$A$2:$A$346, 'DO NOT EDIT - Client List'!$E$2:$E$346), CLEAN('DO NOT EDIT - Client List'!$C$2:$C$346)=_xlpm.t ), _xlpm.k, _xlfn.SEQUENCE(6), _xlpm.nm, IFERROR(INDEX(_xlpm.data, _xlpm.k, 1), ""), _xlpm.dt_raw, IFERROR(INDEX(_xlpm.data, _xlpm.k, 2), ""), _xlpm.dt_num, IF( ISNUMBER(_xlpm.dt_raw), _xlpm.dt_raw, IFERROR(DATEVALUE(_xlpm.dt_raw), 0) ), TRANSPOSE( IF(_xlpm.nm="","", _xlpm.nm & IF(_xlpm.dt_num=0, "", " - " & TEXT(_xlpm.dt_num,"m/d/yyyy")) ) ) ), "")} -> SPRINGFIELD WATER AND SEWER COMMISSION - 6/22/2026 | I50: AGAWAM, TOWN OF
B51: {=IF(SUM(COUNTIF($H51:$N51,{"*TOWN OF*","*CITY OF*"}))>0,"✓","")} | C51: =IF(AND($B51="",COUNTA($H51:$N51)>0),"✓","") -> ✓ | D51: Amherst | E51: City | F51: Hampshire | G51: 3 | H51: {=IFERROR( _xlfn.LET( _xlpm.clean, _xlfn.LAMBDA(_xlpm.x, TRIM(SUBSTITUTE(_xlpm.x,CHAR(160)," "))), _xlpm.t, CLEAN($D51), _xlpm.data, _xlfn._xlws.FILTER( CHOOSE({1,2}, 'DO NOT EDIT - Client List'!$A$2:$A$346, 'DO NOT EDIT - Client List'!$E$2:$E$346), CLEAN('DO NOT EDIT - Client List'!$C$2:$C$346)=_xlpm.t ), _xlpm.k, _xlfn.SEQUENCE(6), _xlpm.nm, IFERROR(INDEX(_xlpm.data, _xlpm.k, 1), ""), _xlpm.dt_raw, IFERROR(INDEX(_xlpm.data, _xlpm.k, 2), ""), _xlpm.dt_num, IF( ISNUMBER(_xlpm.dt_raw), _xlpm.dt_raw, IFERROR(DATEVALUE(_xlpm.dt_raw), 0) ), TRANSPOSE( IF(_xlpm.nm="","", _xlpm.nm & IF(_xlpm.dt_num=0, "", " - " & TEXT(_xlpm.dt_num,"m/d/yyyy")) ) ) ), "")}
B52: {=IF(SUM(COUNTIF($H52:$N52,{"*TOWN OF*","*CITY OF*"}))>0,"✓","")} -> ✓ | C52: =IF(AND($B52="",COUNTA($H52:$N52)>0),"✓","") | D52: Chicopee | E52: City | F52: Hampden | G52: 3 | H52: {=IFERROR( _xlfn.LET( _xlpm.clean, _xlfn.LAMBDA(_xlpm.x, TRIM(SUBSTITUTE(_xlpm.x,CHAR(160)," "))), _xlpm.t, CLEAN($D52), _xlpm.data, _xlfn._xlws.FILTER( CHOOSE({1,2}, 'DO NOT EDIT - Client List'!$A$2:$A$346, 'DO NOT EDIT - Client List'!$E$2:$E$346), CLEAN('DO NOT EDIT - Client List'!$C$2:$C$346)=_xlpm.t ), _xlpm.k, _xlfn.SEQUENCE(6), _xlpm.nm, IFERROR(INDEX(_xlpm.data, _xlpm.k, 1), ""), _xlpm.dt_raw, IFERROR(INDEX(_xlpm.data, _xlpm.k, 2), ""), _xlpm.dt_num, IF( ISNUMBER(_xlpm.dt_raw), _xlpm.dt_raw, IFERROR(DATEVALUE(_xlpm.dt_raw), 0) ), TRANSPOSE( IF(_xlpm.nm="","", _xlpm.nm & IF(_xlpm.dt_num=0, "", " - " & TEXT(_xlpm.dt_num,"m/d/yyyy")) ) ) ), "")} -> CHICOPEE, CITY OF
B53: {=IF(SUM(COUNTIF($H53:$N53,{"*TOWN OF*","*CITY OF*"}))>0,"✓","")} -> ✓ | C53: =IF(AND($B53="",COUNTA($H53:$N53)>0),"✓","") | D53: Easthampton | E53: City | F53: Hampshire | G53: 3 | H53: {=IFERROR( _xlfn.LET( _xlpm.clean, _xlfn.LAMBDA(_xlpm.x, TRIM(SUBSTITUTE(_xlpm.x,CHAR(160)," "))), _xlpm.t, CLEAN($D53), _xlpm.data, _xlfn._xlws.FILTER( CHOOSE({1,2}, 'DO NOT EDIT - Client List'!$A$2:$A$346, 'DO NOT EDIT - Client List'!$E$2:$E$346), CLEAN('DO NOT EDIT - Client List'!$C$2:$C$346)=_xlpm.t ), _xlpm.k, _xlfn.SEQUENCE(6), _xlpm.nm, IFERROR(INDEX(_xlpm.data, _xlpm.k, 1), ""), _xlpm.dt_raw, IFERROR(INDEX(_xlpm.data, _xlpm.k, 2), ""), _xlpm.dt_num, IF( ISNUMBER(_xlpm.dt_raw), _xlpm.dt_raw, IFERROR(DATEVALUE(_xlpm.dt_raw), 0) ), TRANSPOSE( IF(_xlpm.nm="","", _xlpm.nm & IF(_xlpm.dt_num=0, "", " - " & TEXT(_xlpm.dt_num,"m/d/yyyy")) ) ) ), "")} -> EASTHAMPTON, CITY OF
B54: {=IF(SUM(COUNTIF($H54:$N54,{"*TOWN OF*","*CITY OF*"}))>0,"✓","")} -> ✓ | C54: =IF(AND($B54="",COUNTA($H54:$N54)>0),"✓","") | D54: Hadley | E54: Town | F54: Hampshire | G54: 3 | H54: {=IFERROR( _xlfn.LET( _xlpm.clean, _xlfn.LAMBDA(_xlpm.x, TRIM(SUBSTITUTE(_xlpm.x,CHAR(160)," "))), _xlpm.t, CLEAN($D54), _xlpm.data, _xlfn._xlws.FILTER( CHOOSE({1,2}, 'DO NOT EDIT - Client List'!$A$2:$A$346, 'DO NOT EDIT - Client List'!$E$2:$E$346), CLEAN('DO NOT EDIT - Client List'!$C$2:$C$346)=_xlpm.t ), _xlpm.k, _xlfn.SEQUENCE(6), _xlpm.nm, IFERROR(INDEX(_xlpm.data, _xlpm.k, 1), ""), _xlpm.dt_raw, IFERROR(INDEX(_xlpm.data, _xlpm.k, 2), ""), _xlpm.dt_num, IF( ISNUMBER(_xlpm.dt_raw), _xlpm.dt_raw, IFERROR(DATEVALUE(_xlpm.dt_raw), 0) ), TRANSPOSE( IF(_xlpm.nm="","", _xlpm.nm & IF(_xlpm.dt_num=0, "", " - " & TEXT(_xlpm.dt_num,"m/d/yyyy")) ) ) ), "")} -> HADLEY, TOWN OF
B55: {=IF(SUM(COUNTIF($H55:$N55,{"*TOWN OF*","*CITY OF*"}))>0,"✓","")} -> ✓ | C55: =IF(AND($B55="",COUNTA($H55:$N55)>0),"✓","") | D55: Hatfield | E55: Town | F55: Hampshire | G55: 3 | H55: {=IFERROR( _xlfn.LET( _xlpm.clean, _xlfn.LAMBDA(_xlpm.x, TRIM(SUBSTITUTE(_xlpm.x,CHAR(160)," "))), _xlpm.t, CLEAN($D55), _xlpm.data, _xlfn._xlws.FILTER( CHOOSE({1,2}, 'DO NOT EDIT - Client List'!$A$2:$A$346, 'DO NOT EDIT - Client List'!$E$2:$E$346), CLEAN('DO NOT EDIT - Client List'!$C$2:$C$346)=_xlpm.t ), _xlpm.k, _xlfn.SEQUENCE(6), _xlpm.nm, IFERROR(INDEX(_xlpm.data, _xlpm.k, 1), ""), _xlpm.dt_raw, IFERROR(INDEX(_xlpm.data, _xlpm.k, 2), ""), _xlpm.dt_num, IF( ISNUMBER(_xlpm.dt_raw), _xlpm.dt_raw, IFERROR(DATEVALUE(_xlpm.dt_raw), 0) ), TRANSPOSE( IF(_xlpm.nm="","", _xlpm.nm & IF(_xlpm.dt_num=0, "", " - " & TEXT(_xlpm.dt_num,"m/d/yyyy")) ) ) ), "")} -> HATFIELD, TOWN OF
B56: {=IF(SUM(COUNTIF($H56:$N56,{"*TOWN OF*","*CITY OF*"}))>0,"✓","")} | C56: =IF(AND($B56="",COUNTA($H56:$N56)>0),"✓","") -> ✓ | D56: Holyoke | E56: City | F56: Hampden | G56: 3 | H56: {=IFERROR( _xlfn.LET( _xlpm.clean, _xlfn.LAMBDA(_xlpm.x, TRIM(SUBSTITUTE(_xlpm.x,CHAR(160)," "))), _xlpm.t, CLEAN($D56), _xlpm.data, _xlfn._xlws.FILTER( CHOOSE({1,2}, 'DO NOT EDIT - Client List'!$A$2:$A$346, 'DO NOT EDIT - Client List'!$E$2:$E$346), CLEAN('DO NOT EDIT - Client List'!$C$2:$C$346)=_xlpm.t ), _xlpm.k, _xlfn.SEQUENCE(6), _xlpm.nm, IFERROR(INDEX(_xlpm.data, _xlpm.k, 1), ""), _xlpm.dt_raw, IFERROR(INDEX(_xlpm.data, _xlpm.k, 2), ""), _xlpm.dt_num, IF( ISNUMBER(_xlpm.dt_raw), _xlpm.dt_raw, IFERROR(DATEVALUE(_xlpm.dt_raw), 0) ), TRANSPOSE( IF(_xlpm.nm="","", _xlpm.nm & IF(_xlpm.dt_num=0, "", " - " & TEXT(_xlpm.dt_num,"m/d/yyyy")) ) ) ), "")}
B57: {=IF(SUM(COUNTIF($H57:$N57,{"*TOWN OF*","*CITY OF*"}))>0,"✓","")} | C57: =IF(AND($B57="",COUNTA($H57:$N57)>0),"✓","") -> ✓ | D57: Longmeadow | E57: Town | F57: Hampden | G57: 3 | H57: {=IFERROR( _xlfn.LET( _xlpm.clean, _xlfn.LAMBDA(_xlpm.x, TRIM(SUBSTITUTE(_xlpm.x,CHAR(160)," "))), _xlpm.t, CLEAN($D57), _xlpm.data, _xlfn._xlws.FILTER( CHOOSE({1,2}, 'DO NOT EDIT - Client List'!$A$2:$A$346, 'DO NOT EDIT - Client List'!$E$2:$E$346), CLEAN('DO NOT EDIT - Client List'!$C$2:$C$346)=_xlpm.t ), _xlpm.k, _xlfn.SEQUENCE(6), _xlpm.nm, IFERROR(INDEX(_xlpm.data, _xlpm.k, 1), ""), _xlpm.dt_raw, IFERROR(INDEX(_xlpm.data, _xlpm.k, 2), ""), _xlpm.dt_num, IF( ISNUMBER(_xlpm.dt_raw), _xlpm.dt_raw, IFERROR(DATEVALUE(_xlpm.dt_raw), 0) ), TRANSPOSE( IF(_xlpm.nm="","", _xlpm.nm & IF(_xlpm.dt_num=0, "", " - " & TEXT(_xlpm.dt_num,"m/d/yyyy")) ) ) ), "")}
B58: {=IF(SUM(COUNTIF($H58:$N58,{"*TOWN OF*","*CITY OF*"}))>0,"✓","")} -> ✓ | C58: =IF(AND($B58="",COUNTA($H58:$N58)>0),"✓","") | D58: Northampton | E58: City | F58: Hampshire | G58: 3 | H58: {=IFERROR( _xlfn.LET( _xlpm.clean, _xlfn.LAMBDA(_xlpm.x, TRIM(SUBSTITUTE(_xlpm.x,CHAR(160)," "))), _xlpm.t, CLEAN($D58), _xlpm.data, _xlfn._xlws.FILTER( CHOOSE({1,2}, 'DO NOT EDIT - Client List'!$A$2:$A$346, 'DO NOT EDIT - Client List'!$E$2:$E$346), CLEAN('DO NOT EDIT - Client List'!$C$2:$C$346)=_xlpm.t ), _xlpm.k, _xlfn.SEQUENCE(6), _xlpm.nm, IFERROR(INDEX(_xlpm.data, _xlpm.k, 1), ""), _xlpm.dt_raw, IFERROR(INDEX(_xlpm.data, _xlpm.k, 2), ""), _xlpm.dt_num, IF( ISNUMBER(_xlpm.dt_raw), _xlpm.dt_raw, IFERROR(DATEVALUE(_xlpm.dt_raw), 0) ), TRANSPOSE( IF(_xlpm.nm="","", _xlpm.nm & IF(_xlpm.dt_num=0, "", " - " & TEXT(_xlpm.dt_num,"m/d/yyyy")) ) ) ), "")} -> NORTHAMPTON, CITY OF | I58: HIGHLAND VALLEY ELDER SERVICES | J58: FRIENDS OF FORBES LIBRARY | K58: FORBES LIBRARY - 2/23/2026
B59: {=IF(SUM(COUNTIF($H59:$N59,{"*TOWN OF*","*CITY OF*"}))>0,"✓","")} -> ✓ | C59: =IF(AND($B59="",COUNTA($H59:$N59)>0),"✓","") | D59: South Hadley | E59: Town | F59: Hampshire | G59: 3 | H59: {=IFERROR( _xlfn.LET( _xlpm.clean, _xlfn.LAMBDA(_xlpm.x, TRIM(SUBSTITUTE(_xlpm.x,CHAR(160)," "))), _xlpm.t, CLEAN($D59), _xlpm.data, _xlfn._xlws.FILTER( CHOOSE({1,2}, 'DO NOT EDIT - Client List'!$A$2:$A$346, 'DO NOT EDIT - Client List'!$E$2:$E$346), CLEAN('DO NOT EDIT - Client List'!$C$2:$C$346)=_xlpm.t ), _xlpm.k, _xlfn.SEQUENCE(6), _xlpm.nm, IFERROR(INDEX(_xlpm.data, _xlpm.k, 1), ""), _xlpm.dt_raw, IFERROR(INDEX(_xlpm.data, _xlpm.k, 2), ""), _xlpm.dt_num, IF( ISNUMBER(_xlpm.dt_raw), _xlpm.dt_raw, IFERROR(DATEVALUE(_xlpm.dt_raw), 0) ), TRANSPOSE( IF(_xlpm.nm="","", _xlpm.nm & IF(_xlpm.dt_num=0, "", " - " & TEXT(_xlpm.dt_num,"m/d/yyyy")) ) ) ), "")} -> SOUTH HADLEY, TOWN OF - 1/29/2026 | I59: SOUTH HADLEY FIRE DISTRICT #1
B60: {=IF(SUM(COUNTIF($H60:$N60,{"*TOWN OF*","*CITY OF*"}))>0,"✓","")} -> ✓ | C60: =IF(AND($B60="",COUNTA($H60:$N60)>0),"✓","") | D60: Southampton | E60: Town | F60: Hampshire | G60: 3 | H60: {=IFERROR( _xlfn.LET( _xlpm.clean, _xlfn.LAMBDA(_xlpm.x, TRIM(SUBSTITUTE(_xlpm.x,CHAR(160)," "))), _xlpm.t, CLEAN($D60), _xlpm.data, _xlfn._xlws.FILTER( CHOOSE({1,2}, 'DO NOT EDIT - Client List'!$A$2:$A$346, 'DO NOT EDIT - Client List'!$E$2:$E$346), CLEAN('DO NOT EDIT - Client List'!$C$2:$C$346)=_xlpm.t ), _xlpm.k, _xlfn.SEQUENCE(6), _xlpm.nm, IFERROR(INDEX(_xlpm.data, _xlpm.k, 1), ""), _xlpm.dt_raw, IFERROR(INDEX(_xlpm.data, _xlpm.k, 2), ""), _xlpm.dt_num, IF( ISNUMBER(_xlpm.dt_raw), _xlpm.dt_raw, IFERROR(DATEVALUE(_xlpm.dt_raw), 0) ), TRANSPOSE( IF(_xlpm.nm="","", _xlpm.nm & IF(_xlpm.dt_num=0, "", " - " & TEXT(_xlpm.dt_num,"m/d/yyyy")) ) ) ), "")} -> SOUTHAMPTON, TOWN OF
B61: {=IF(SUM(COUNTIF($H61:$N61,{"*TOWN OF*","*CITY OF*"}))>0,"✓","")} -> ✓ | C61: =IF(AND($B61="",COUNTA($H61:$N61)>0),"✓","") | D61: Southwick | E61: Town | F61: Hampden | G61: 3 | H61: {=IFERROR( _xlfn.LET( _xlpm.clean, _xlfn.LAMBDA(_xlpm.x, TRIM(SUBSTITUTE(_xlpm.x,CHAR(160)," "))), _xlpm.t, CLEAN($D61), _xlpm.data, _xlfn._xlws.FILTER( CHOOSE({1,2}, 'DO NOT EDIT - Client List'!$A$2:$A$346, 'DO NOT EDIT - Client List'!$E$2:$E$346), CLEAN('DO NOT EDIT - Client List'!$C$2:$C$346)=_xlpm.t ), _xlpm.k, _xlfn.SEQUENCE(6), _xlpm.nm, IFERROR(INDEX(_xlpm.data, _xlpm.k, 1), ""), _xlpm.dt_raw, IFERROR(INDEX(_xlpm.data, _xlpm.k, 2), ""), _xlpm.dt_num, IF( ISNUMBER(_xlpm.dt_raw), _xlpm.dt_raw, IFERROR(DATEVALUE(_xlpm.dt_raw), 0) ), TRANSPOSE( IF(_xlpm.nm="","", _xlpm.nm & IF(_xlpm.dt_num=0, "", " - " & TEXT(_xlpm.dt_num,"m/d/yyyy")) ) ) ), "")} -> SOUTHWICK, TOWN OF
...

Sheet Dashboard
A1: Region: | B1: # of clients | C1: Advisor:
A2: 1 | B2: =COUNTIF('1-Sue'!A2:A57,"*") -> 15 | C2: Sue | F2: # of clients | H2: Done | I2: % Done
A3: 2 | B3: =COUNTIF('2-Sue'!A2:A34,"*") -> 11 | C3: sue | E3: Sue | F3: =B2+B3+B4+B5+B7 -> 89 | H3: =SUM('DO NOT EDIT - Client List'!J2:J67,'DO NOT EDIT - Client List'!J94:J114) -> 5 | I3: =H3/F3 -> 0.056179775
A4: 3 | B4: =COUNTIF('3-Sue'!A2:A60,"*") -> 21 | C4: sue | E4: Michelle | F4: =B17+B15+B16+B14 -> 79 | H4: =SUM('DO NOT EDIT - Client List'!J266:J346) -> 0 | I4: =H4/F4 -> 0
A5: 4 | B5: =COUNTIF('4-Sue'!A2:A54,"*") -> 20 | C5: sue | E5: Brian | F5: =B6+B8+B11 -> 82 | H5: =SUM('DO NOT EDIT - Client List'!J68:J93,'DO NOT EDIT - Client List'!J115:J151,'DO NOT EDIT - Client List'!J213:J231) -> 0 | I5: =H5/F5 -> 0
A6: 5 | B6: =COUNTIF('5-Brian'!A2:A59,"*") -> 25 | C6: Brian | E6: Kath | F6: =B13+B9+B10 -> 82 | H6: =SUM('DO NOT EDIT - Client List'!J152:J212,'DO NOT EDIT - Client List'!J242:J265) -> 13 | I6: =H6/F6 -> 0.15853659
A7: 6 | B7: =COUNTIF('6-Sue'!A2:A61,"*") -> 22 | C7: Sue
A8: 7 | B8: =COUNTIF('7-Brian'!A2:A64,"*") -> 38 | C8: Brian | E8: BMK | F8: =B12 -> 10 | H8: =SUM('DO NOT EDIT - Client List'!J232:J241) -> 0 | I8: =H8/F8 -> 0
A9: 8 | B9: =COUNTIF('8-Kath'!A2:A62,"*") -> 31 | C9: Kath
A10: 9 | B10: =COUNTIF('9-Kath'!A2:A63,"*") -> 28 | C10: Kath | E10: TOTAL | F10: =SUM(B2:B17) -> 342 | H10: =SUM(H3:H8) -> 18 | I10: =H10/F10 -> 0.052631579
A11: 10 | B11: =COUNTIF('10-Brian'!A2:A64,"*") -> 19 | C11: Brian
A12: 11 | B12: =COUNTIF('11-B,M,K'!A2:A65,"*") -> 10 | C12: B,M,K
A13: 12 | B13: =COUNTIF('12-Kath'!A2:A66,"*") -> 23 | C13: Kath
A14: 13 | B14: =COUNTIF('13-Michelle'!A2:A66,"*") -> 18 | C14: Michelle
A15: 14 | B15: =COUNTIF('14-Michelle'!A2:A68,"*") -> 23 | C15: Michelle
A16: 15 | B16: =COUNTIF('15-Michelle'!A2:A69,"*") -> 21 | C16: Michelle
A17: 16 | B17: =COUNTIF('16-Michelle'!A2:A70,"*") -> 17 | C17: Michelle
B18: =SUM(B2:B17) -> 342
B19: https://datawrapper.dwcdn.net/TvOY0/6/

Sheet 1-Sue
A1: Household Name | B1: City | C1: Community | D1: Region | E1: Last Review | F1: Special Notes | G1: Copy/Material Count | H1: Advisor Number/Kathleen? | I1: NEW review date | J1: Done?
A2: BECKET, TOWN OF | B2: BECKET | C2: Becket | D2: 1 | E2: 46037 | F2: - | G2: - | H2: - | I2: 8/25 @ 9 | J2: 1
A3: BECKET BROADBAND DISTRICT | C3: Becket | D3: 1 | E3: 46037 | F3: - | G3: - | H3: - | I3: 8/25 @9:30 | J3: 1
A4: BLANDFORD, TOWN OF | B4: BLANDFORD | C4: Blandford | D4: 1 | E4: 46001 | F4: - | G4: Sara H (Blandford, Chester, Monterey) | H4: -
A5: PORTER MEMORIAL LIBRARY | D5: 1 | E5: - | F5: - | G5: - | H5: -
A6: CHESTER, TOWN OF | B6: CHESTER | C6: Chester | D6: 1 | E6: 46001 | F6: - | G6: Sara H (Blandford, Chester, Monterey) | H6: -
A7: EGREMONT, TOWN OF | B7: EGREMONT | C7: Egremont | D7: 1 | E7: 45739 | F7: - | G7: - | H7: -
A8: GREAT BARRINGTON, TOWN OF | B8: GREAT BARRINGTON | C8: Great Barrington | D8: 1 | E8: 5/13/ @ noon ? | F8: - | G8: - | H8: -
A9: MONTEREY, TOWN OF | D9: 1 | F9: - | G9: - | H9: -
A10: LEE, TOWN OF | B10: LEE | C10: Lee | D10: 1 | E10: sent email | F10: - | G10: Sue can't do this one (conflict of interest) | H10: -
A11: LENOX, TOWN OF | B11: LENOX | C11: Lenox | D11: 1 | E11: Sent reviews | F11: Lunch | H11: - | I11: 9/17 @ 9:30
A12: LAKE BUEL PRESERVATION DISTRICT | B12: NEW MARLBOROUGH | C12: New Marlborough | D12: 1 | E12: 5/13 @ 10:30 | F12: - | G12: - | H12: -
A13: OTIS, TOWN OF | B13: OTIS | C13: Otis | D13: 1 | F13: - | H13: - | I13: 9/30 @10:30
A14: RICHMOND, TOWN OF | B14: Richmond | C14: Richmond | D14: 1 | E14: 5/13 @ 3:30 | F14: Lunch | G14: - | H14: - | I14: 9/17 @ 11:30 (lunch)
A15: STOCKBRIDGE, TOWN OF | B15: STOCKBRIDGE | C15: Stockbridge | D15: 1 | E15: 5/4 @ 12pm LUNCH | F15: - | H15: -
A16: WEST STOCKBRIDGE, TOWN OF | B16: WEST STOCKBRIDGE | C16: West Stockbridge | D16: 1 | E16: 4/28 @1pm (meet in Cheshire) | F16: - | G16: - | H16: - | I16: 9/14 @ 12:30

Sheet 2-Sue
A1: Household Name | B1: City | C1: Community | D1: Region | E1: Last Review | F1: Special Notes | G1: Copy/Material Count | H1: Advisor Number/Kathleen? | I1: NEW review date | J1: Done?
A2: ROWE, TOWN OF | B2: ROWE | C2: Rowe | D2: =_xlfn.XLOOKUP(C2,'Territory List'!$D$2:$D$352,'Territory List'!$G$2:$G$352) -> 2 | E2: 46099 | F2: - | G2: - | H2: -
A3: ADAMS, TOWN OF | B3: ADAMS | C3: Adams | D3: =_xlfn.XLOOKUP(C3,'Territory List'!$D$2:$D$352,'Territory List'!$G$2:$G$352) -> 2 | E3: 46050 | F3: - | G3: 3 | H3: - | I3: 9/9 @9am
A4: CHESHIRE, TOWN OF | B4: CHESHIRE | C4: Cheshire | D4: =_xlfn.XLOOKUP(C4,'Territory List'!$D$2:$D$352,'Territory List'!$G$2:$G$352) -> 2 | E4: 46140 | F4: - | G4: 3 | H4: - | I4: 9/14 @12:30 in W. SB
A5: CUMMINGTON, TOWN OF | B5: CUMMINGTON | C5: Cummington | D5: =_xlfn.XLOOKUP(C5,'Territory List'!$D$2:$D$352,'Territory List'!$G$2:$G$352) -> 2 | E5: 46030 | F5: Allan K also in Goshen | G5: - | H5: - | I5: 9/10 @9:30
A6: GOSHEN, TOWN OF | B6: 4 | C6: 46030 | D6: 2 | E6: 46030 | F6: - | G6: - | H6: - | I6: 9/10 @ 9:30
A7: LANESBOROUGH VILLAGE FIRE & WATER DISTRICT | B7: Lanesborough | C7: Lanesborough | D7: =_xlfn.XLOOKUP(C7,'Territory List'!$D$2:$D$352,'Territory List'!$G$2:$G$352) -> 2 | E7: 5/12 @12pm | F7: Treasurer works in Lanesborough/do same day | G7: - | H7: - | I7: 8/28 @ 12:30
